fill ~0 ~189 ~56 ~3 ~189 ~57 minecraft:leaves ["persistent_bit"=false,"update_bit"=false,"old_leaf_type"="jungle"]
fill ~1 ~118 ~57 ~5 ~118 ~57 minecraft:leaves ["persistent_bit"=false,"update_bit"=false,"old_leaf_type"="oak"]
fill ~1 ~118 ~58 ~1 ~119 ~61 minecraft:leaves ["persistent_bit"=false,"update_bit"=false,"old_leaf_type"="oak"]
fill ~1 ~152 ~55 ~1 ~152 ~57 minecraft:leaves ["persistent_bit"=false,"update_bit"=false,"old_leaf_type"="spruce"]
fill ~1 ~153 ~56 ~1 ~153 ~57 minecraft:snow_layer ["covered_bit"=false,"height"=0]
fill ~1 ~154 ~55 ~5 ~154 ~55 minecraft:leaves ["persistent_bit"=true,"update_bit"=false,"old_leaf_type"="spruce"]
fill ~1 ~154 ~56 ~2 ~154 ~57 minecraft:leaves ["persistent_bit"=true,"update_bit"=false,"old_leaf_type"="spruce"]
fill ~1 ~155 ~55 ~2 ~155 ~55 minecraft:snow_layer ["covered_bit"=false,"height"=1]
fill ~1 ~186 ~48 ~5 ~186 ~48 minecraft:leaves ["persistent_bit"=false,"update_bit"=false,"old_leaf_type"="jungle"]
fill ~1 ~186 ~49 ~1 ~187 ~51 minecraft:leaves ["persistent_bit"=false,"update_bit"=false,"old_leaf_type"="jungle"]
fill ~1 ~187 ~48 ~4 ~187 ~48 minecraft:leaves ["persistent_bit"=false,"update_bit"=false,"old_leaf_type"="jungle"]
fill ~1 ~187 ~52 ~5 ~187 ~52 minecraft:leaves ["persistent_bit"=false,"update_bit"=false,"old_leaf_type"="jungle"]
fill ~1 ~189 ~53 ~10 ~189 ~54 minecraft:leaves ["persistent_bit"=false,"update_bit"=false,"old_leaf_type"="jungle"]
fill ~1 ~189 ~55 ~3 ~189 ~60 minecraft:leaves ["persistent_bit"=false,"update_bit"=false,"old_leaf_type"="jungle"]
fill ~1 ~190 ~56 ~3 ~190 ~57 minecraft:leaves ["persistent_bit"=false,"update_bit"=false,"old_leaf_type"="jungle"]
fill ~2 ~0 ~46 ~102 ~8 ~60 minecraft:stone ["stone_type"="stone"]
fill ~2 ~9 ~46 ~2 ~11 ~46 minecraft:dirt ["dirt_type"="normal"]
fill ~2 ~9 ~47 ~102 ~9 ~50 minecraft:stone ["stone_type"="stone"]
fill ~2 ~9 ~51 ~2 ~11 ~51 minecraft:dirt ["dirt_type"="normal"]
fill ~2 ~9 ~52 ~102 ~10 ~52 minecraft:stone ["stone_type"="stone"]
fill ~2 ~9 ~53 ~102 ~9 ~56 minecraft:stone ["stone_type"="stone"]
fill ~2 ~9 ~57 ~2 ~11 ~57 minecraft:dirt ["dirt_type"="normal"]
fill ~2 ~9 ~58 ~102 ~9 ~60 minecraft:stone ["stone_type"="stone"]
fill ~2 ~10 ~47 ~2 ~11 ~48 minecraft:dirt ["dirt_type"="normal"]
fill ~2 ~10 ~49 ~102 ~10 ~49 minecraft:stone ["stone_type"="stone"]
fill ~2 ~10 ~50 ~2 ~11 ~51 minecraft:dirt ["dirt_type"="normal"]
fill ~2 ~10 ~53 ~2 ~11 ~55 minecraft:dirt ["dirt_type"="normal"]
fill ~2 ~10 ~56 ~102 ~10 ~56 minecraft:stone ["stone_type"="stone"]
fill ~2 ~10 ~58 ~2 ~11 ~59 minecraft:dirt ["dirt_type"="normal"]
fill ~2 ~10 ~60 ~102 ~10 ~60 minecraft:stone ["stone_type"="stone"]
fill ~2 ~11 ~49 ~2 ~11 ~60 minecraft:dirt ["dirt_type"="normal"]
fill ~2 ~12 ~46 ~3 ~12 ~46 minecraft:grass
fill ~2 ~12 ~47 ~2 ~12 ~60 minecraft:grass
fill ~2 ~13 ~46 ~2 ~13 ~48 minecraft:tallgrass ["tall_grass_type"="tall"]
fill ~2 ~13 ~53 ~3 ~13 ~55 minecraft:tallgrass ["tall_grass_type"="tall"]
fill ~2 ~13 ~58 ~2 ~13 ~59 minecraft:tallgrass ["tall_grass_type"="tall"]
fill ~2 ~14 ~55 ~6 ~14 ~55 minecraft:leaves ["persistent_bit"=false,"update_bit"=false,"old_leaf_type"="oak"]
fill ~2 ~14 ~56 ~2 ~15 ~58 minecraft:leaves ["persistent_bit"=false,"update_bit"=false,"old_leaf_type"="oak"]
fill ~2 ~16 ~39 ~6 ~16 ~39 minecraft:leaves ["persistent_bit"=false,"update_bit"=false,"old_leaf_type"="oak"]
fill ~2 ~16 ~40 ~2 ~17 ~42 minecraft:leaves ["persistent_bit"=false,"update_bit"=false,"old_leaf_type"="oak"]
fill ~2 ~16 ~43 ~6 ~16 ~43 minecraft:leaves ["persistent_bit"=false,"update_bit"=false,"old_leaf_type"="oak"]
fill ~2 ~22 ~46 ~102 ~24 ~47 minecraft:stone ["stone_type"="stone"]
fill ~2 ~22 ~48 ~102 ~23 ~50 minecraft:stone ["stone_type"="stone"]
fill ~2 ~23 ~51 ~102 ~24 ~52 minecraft:stone ["stone_type"="stone"]
fill ~2 ~24 ~48 ~101 ~25 ~55 minecraft:stone ["stone_type"="stone"]
fill ~2 ~24 ~56 ~102 ~24 ~57 minecraft:stone ["stone_type"="stone"]
fill ~2 ~24 ~58 ~93 ~40 ~58 minecraft:stone ["stone_type"="stone"]
fill ~2 ~24 ~59 ~99 ~24 ~59 minecraft:stone ["stone_type"="stone"]
fill ~2 ~24 ~60 ~93 ~24 ~60 minecraft:stone ["stone_type"="stone"]
fill ~2 ~25 ~46 ~101 ~25 ~55 minecraft:stone ["stone_type"="stone"]
fill ~2 ~25 ~56 ~94 ~40 ~56 minecraft:stone ["stone_type"="stone"]
fill ~2 ~25 ~57 ~93 ~39 ~58 minecraft:stone ["stone_type"="stone"]
fill ~2 ~25 ~59 ~84 ~40 ~59 minecraft:stone ["stone_type"="stone"]
fill ~2 ~25 ~60 ~84 ~38 ~60 minecraft:stone ["stone_type"="stone"]
fill ~2 ~26 ~46 ~96 ~26 ~47 minecraft:stone ["stone_type"="stone"]
fill ~2 ~26 ~48 ~93 ~26 ~58 minecraft:stone ["stone_type"="stone"]
fill ~2 ~27 ~46 ~91 ~37 ~46 minecraft:stone ["stone_type"="stone"]
fill ~2 ~27 ~47 ~91 ~36 ~47 minecraft:stone ["stone_type"="stone"]
fill ~2 ~27 ~48 ~91 ~35 ~60 minecraft:stone ["stone_type"="stone"]
fill ~2 ~36 ~48 ~2 ~39 ~48 minecraft:netherrack
fill ~2 ~36 ~49 ~102 ~37 ~49 minecraft:stone ["stone_type"="stone"]
fill ~2 ~36 ~50 ~102 ~36 ~50 minecraft:stone ["stone_type"="stone"]
fill ~2 ~36 ~51 ~100 ~36 ~60 minecraft:stone ["stone_type"="stone"]
fill ~2 ~37 ~47 ~2 ~39 ~48 minecraft:netherrack
fill ~2 ~37 ~50 ~2 ~39 ~51 minecraft:netherrack
fill ~2 ~37 ~52 ~102 ~37 ~52 minecraft:stone ["stone_type"="stone"]
fill ~2 ~37 ~53 ~2 ~39 ~53 minecraft:netherrack
fill ~2 ~37 ~54 ~102 ~37 ~60 minecraft:stone ["stone_type"="stone"]
fill ~2 ~38 ~46 ~2 ~39 ~54 minecraft:netherrack
fill ~2 ~38 ~55 ~102 ~41 ~55 minecraft:stone ["stone_type"="stone"]
fill ~2 ~39 ~60 ~2 ~41 ~60 minecraft:dirt ["dirt_type"="normal"]
fill ~2 ~40 ~57 ~2 ~41 ~57 minecraft:dirt ["dirt_type"="normal"]
fill ~2 ~41 ~56 ~2 ~41 ~60 minecraft:dirt ["dirt_type"="normal"]
fill ~2 ~42 ~55 ~8 ~42 ~55 minecraft:grass
fill ~2 ~42 ~56 ~7 ~42 ~56 minecraft:grass
fill ~2 ~42 ~57 ~6 ~42 ~57 minecraft:grass
fill ~2 ~42 ~58 ~2 ~42 ~60 minecraft:grass
fill ~2 ~52 ~46 ~102 ~59 ~46 minecraft:stone ["stone_type"="stone"]
fill ~2 ~52 ~47 ~102 ~57 ~48 minecraft:stone ["stone_type"="stone"]
fill ~2 ~52 ~49 ~102 ~56 ~54 minecraft:stone ["stone_type"="stone"]
fill ~2 ~52 ~55 ~102 ~55 ~57 minecraft:stone ["stone_type"="stone"]
fill ~2 ~53 ~58 ~102 ~57 ~60 minecraft:stone ["stone_type"="stone"]
fill ~2 ~56 ~55 ~101 ~57 ~60 minecraft:stone ["stone_type"="stone"]
fill ~2 ~57 ~49 ~101 ~57 ~60 minecraft:stone ["stone_type"="stone"]
fill ~2 ~58 ~47 ~98 ~59 ~47 minecraft:stone ["stone_type"="stone"]
fill ~2 ~58 ~48 ~97 ~59 ~49 minecraft:stone ["stone_type"="stone"]
fill ~2 ~58 ~50 ~95 ~61 ~50 minecraft:stone ["stone_type"="stone"]
fill ~2 ~58 ~51 ~94 ~75 ~51 minecraft:stone ["stone_type"="stone"]
fill ~2 ~58 ~52 ~94 ~63 ~52 minecraft:stone ["stone_type"="stone"]
fill ~2 ~58 ~53 ~93 ~75 ~54 minecraft:stone ["stone_type"="stone"]
fill ~2 ~58 ~55 ~92 ~75 ~57 minecraft:stone ["stone_type"="stone"]
fill ~2 ~58 ~58 ~91 ~76 ~59 minecraft:stone ["stone_type"="stone"]
fill ~2 ~58 ~60 ~91 ~58 ~60 minecraft:stone ["stone_type"="stone"]
fill ~2 ~59 ~60 ~90 ~78 ~60 minecraft:stone ["stone_type"="stone"]
fill ~2 ~60 ~46 ~98 ~60 ~46 minecraft:stone ["stone_type"="stone"]
fill ~2 ~60 ~47 ~95 ~60 ~50 minecraft:stone ["stone_type"="stone"]
fill ~2 ~61 ~46 ~94 ~74 ~51 minecraft:stone ["stone_type"="stone"]
fill ~2 ~64 ~52 ~93 ~75 ~54 minecraft:stone ["stone_type"="stone"]
fill ~2 ~75 ~46 ~2 ~76 ~60 minecraft:stone ["stone_type"="stone"]
fill ~2 ~77 ~48 ~2 ~77 ~60 minecraft:stone ["stone_type"="stone"]
fill ~2 ~79 ~60 ~4 ~79 ~60 minecraft:magma
fill ~2 ~87 ~46 ~101 ~91 ~48 minecraft:stone ["stone_type"="stone"]
fill ~2 ~87 ~49 ~4 ~109 ~55 minecraft:stone ["stone_type"="stone"]
fill ~2 ~88 ~56 ~102 ~88 ~57 minecraft:stone ["stone_type"="stone"]
fill ~2 ~88 ~60 ~2 ~113 ~60 minecraft:stone ["stone_type"="stone"]
fill ~2 ~89 ~56 ~101 ~91 ~56 minecraft:stone ["stone_type"="stone"]
fill ~2 ~89 ~57 ~101 ~89 ~60 minecraft:stone ["stone_type"="stone"]
fill ~2 ~90 ~57 ~93 ~111 ~57 minecraft:stone ["stone_type"="stone"]
fill ~2 ~90 ~58 ~88 ~112 ~60 minecraft:stone ["stone_type"="stone"]
fill ~2 ~92 ~46 ~92 ~98 ~46 minecraft:stone ["stone_type"="stone"]
fill ~2 ~92 ~47 ~92 ~97 ~49 minecraft:stone ["stone_type"="stone"]
fill ~2 ~92 ~56 ~92 ~113 ~56 minecraft:stone ["stone_type"="stone"]
fill ~2 ~98 ~47 ~91 ~106 ~60 minecraft:stone ["stone_type"="stone"]
fill ~2 ~99 ~46 ~91 ~108 ~46 minecraft:stone ["stone_type"="stone"]
fill ~2 ~107 ~47 ~2 ~109 ~47 minecraft:dirt ["dirt_type"="normal"]
fill ~2 ~107 ~48 ~102 ~108 ~60 minecraft:stone ["stone_type"="stone"]
fill ~2 ~109 ~46 ~2 ~109 ~47 minecraft:dirt ["dirt_type"="normal"]
fill ~2 ~109 ~48 ~2 ~113 ~48 minecraft:stained_hardened_clay ["color"="red"]
fill ~2 ~110 ~46 ~4 ~110 ~47 minecraft:grass
fill ~2 ~110 ~49 ~5 ~110 ~49 minecraft:stained_hardened_clay ["color"="red"]
fill ~2 ~110 ~50 ~2 ~110 ~60 minecraft:stone ["stone_type"="stone"]
fill ~2 ~111 ~49 ~2 ~111 ~52 minecraft:stained_hardened_clay ["color"="red"]
fill ~2 ~111 ~54 ~2 ~114 ~54 minecraft:dirt ["dirt_type"="normal"]
fill ~2 ~111 ~55 ~102 ~112 ~56 minecraft:stone ["stone_type"="stone"]
fill ~2 ~112 ~50 ~2 ~113 ~52 minecraft:stained_hardened_clay ["color"="red"]
fill ~2 ~112 ~53 ~2 ~114 ~54 minecraft:dirt ["dirt_type"="normal"]
fill ~2 ~112 ~57 ~2 ~114 ~57 minecraft:dirt ["dirt_type"="normal"]
fill ~2 ~113 ~49 ~6 ~113 ~52 minecraft:stained_hardened_clay ["color"="red"]
fill ~2 ~113 ~55 ~2 ~114 ~55 minecraft:dirt ["dirt_type"="normal"]
fill ~2 ~113 ~58 ~2 ~114 ~59 minecraft:dirt ["dirt_type"="normal"]
fill ~2 ~114 ~48 ~6 ~114 ~48 minecraft:stone_block_slab4 ["top_slot_bit"=false,"stone_slab_type_4"="stone"]
fill ~2 ~114 ~49 ~2 ~114 ~52 minecraft:double_stone_block_slab4 ["top_slot_bit"=false,"stone_slab_type_4"="stone"]
fill ~2 ~114 ~56 ~2 ~114 ~60 minecraft:dirt ["dirt_type"="normal"]
fill ~2 ~115 ~50 ~2 ~115 ~52 minecraft:stone_block_slab4 ["top_slot_bit"=false,"stone_slab_type_4"="stone"]
fill ~2 ~115 ~53 ~2 ~115 ~60 minecraft:grass
fill ~2 ~116 ~54 ~2 ~116 ~56 minecraft:tallgrass ["tall_grass_type"="tall"]
fill ~2 ~118 ~58 ~4 ~119 ~58 minecraft:leaves ["persistent_bit"=true,"update_bit"=false,"old_leaf_type"="oak"]
fill ~2 ~118 ~59 ~2 ~121 ~59 minecraft:leaves ["persistent_bit"=true,"update_bit"=false,"old_leaf_type"="oak"]
fill ~2 ~118 ~60 ~4 ~119 ~60 minecraft:leaves ["persistent_bit"=true,"update_bit"=false,"old_leaf_type"="oak"]
fill ~2 ~118 ~61 ~4 ~119 ~61 minecraft:leaves ["persistent_bit"=false,"update_bit"=false,"old_leaf_type"="oak"]
fill ~2 ~119 ~57 ~4 ~119 ~57 minecraft:leaves ["persistent_bit"=false,"update_bit"=false,"old_leaf_type"="oak"]
fill ~2 ~123 ~46 ~102 ~128 ~47 minecraft:stone ["stone_type"="stone"]
fill ~2 ~124 ~48 ~102 ~128 ~50 minecraft:stone ["stone_type"="stone"]
fill ~2 ~124 ~51 ~102 ~127 ~60 minecraft:stone ["stone_type"="stone"]
fill ~2 ~128 ~51 ~101 ~130 ~60 minecraft:stone ["stone_type"="stone"]
fill ~2 ~129 ~46 ~101 ~130 ~60 minecraft:stone ["stone_type"="stone"]
fill ~2 ~131 ~46 ~90 ~144 ~54 minecraft:stone ["stone_type"="stone"]
fill ~2 ~131 ~55 ~90 ~143 ~60 minecraft:stone ["stone_type"="stone"]
fill ~2 ~144 ~55 ~2 ~145 ~55 minecraft:packed_ice
fill ~2 ~144 ~56 ~102 ~146 ~58 minecraft:stone ["stone_type"="stone"]
fill ~2 ~144 ~59 ~102 ~145 ~59 minecraft:stone ["stone_type"="stone"]
fill ~2 ~144 ~60 ~12 ~146 ~60 minecraft:stone ["stone_type"="stone"]
fill ~2 ~145 ~46 ~23 ~145 ~46 minecraft:wood ["stripped_bit"=false,"pillar_axis"="y","wood_type"="spruce"]
fill ~2 ~145 ~47 ~102 ~145 ~50 minecraft:stone ["stone_type"="stone"]
fill ~2 ~145 ~51 ~2 ~147 ~51 minecraft:dirt ["dirt_type"="normal"]
fill ~2 ~145 ~52 ~5 ~145 ~54 minecraft:stone ["stone_type"="stone"]
fill ~2 ~146 ~47 ~4 ~146 ~47 minecraft:dirt ["dirt_type"="normal"]
fill ~2 ~146 ~48 ~102 ~146 ~49 minecraft:stone ["stone_type"="stone"]
fill ~2 ~146 ~50 ~2 ~147 ~52 minecraft:dirt ["dirt_type"="normal"]
fill ~2 ~146 ~53 ~102 ~146 ~53 minecraft:stone ["stone_type"="stone"]
fill ~2 ~146 ~54 ~2 ~149 ~54 minecraft:packed_ice
fill ~2 ~146 ~55 ~102 ~147 ~55 minecraft:stone ["stone_type"="stone"]
fill ~2 ~146 ~59 ~15 ~147 ~59 minecraft:stone ["stone_type"="stone"]
fill ~2 ~147 ~47 ~3 ~147 ~47 minecraft:dirt ["dirt_type"="normal"]
fill ~2 ~147 ~48 ~2 ~147 ~53 minecraft:dirt ["dirt_type"="normal"]
fill ~2 ~147 ~56 ~2 ~148 ~58 minecraft:dirt ["dirt_type"="normal"]
fill ~2 ~147 ~60 ~2 ~148 ~60 minecraft:dirt ["dirt_type"="normal"]
fill ~2 ~148 ~49 ~5 ~148 ~49 minecraft:grass
fill ~2 ~148 ~50 ~4 ~148 ~50 minecraft:grass
fill ~2 ~148 ~51 ~3 ~148 ~51 minecraft:grass
fill ~2 ~148 ~52 ~2 ~148 ~53 minecraft:dirt ["dirt_type"="normal"]
fill ~2 ~148 ~55 ~2 ~148 ~60 minecraft:dirt ["dirt_type"="normal"]
fill ~2 ~149 ~49 ~4 ~149 ~49 minecraft:snow_layer ["covered_bit"=false,"height"=0]
fill ~2 ~149 ~50 ~4 ~149 ~50 minecraft:snow_layer ["covered_bit"=false,"height"=1]
fill ~2 ~149 ~51 ~3 ~149 ~51 minecraft:snow_layer ["covered_bit"=false,"height"=1]
fill ~2 ~149 ~52 ~4 ~149 ~52 minecraft:grass
fill ~2 ~149 ~53 ~3 ~149 ~53 minecraft:grass
fill ~2 ~149 ~55 ~8 ~149 ~55 minecraft:grass
fill ~2 ~149 ~56 ~2 ~149 ~60 minecraft:grass
fill ~2 ~150 ~52 ~4 ~150 ~52 minecraft:snow_layer ["covered_bit"=false,"height"=0]
fill ~2 ~150 ~53 ~3 ~150 ~53 minecraft:snow_layer ["covered_bit"=false,"height"=0]
fill ~2 ~150 ~55 ~8 ~150 ~55 minecraft:snow_layer ["covered_bit"=false,"height"=0]
fill ~2 ~150 ~56 ~2 ~150 ~60 minecraft:snow_layer ["covered_bit"=false,"height"=0]
fill ~2 ~152 ~54 ~4 ~152 ~54 minecraft:leaves ["persistent_bit"=false,"update_bit"=false,"old_leaf_type"="spruce"]
fill ~2 ~152 ~55 ~4 ~152 ~55 minecraft:leaves ["persistent_bit"=true,"update_bit"=false,"old_leaf_type"="spruce"]
fill ~2 ~152 ~56 ~2 ~154 ~56 minecraft:leaves ["persistent_bit"=true,"update_bit"=false,"old_leaf_type"="spruce"]
fill ~2 ~152 ~57 ~5 ~152 ~57 minecraft:leaves ["persistent_bit"=true,"update_bit"=false,"old_leaf_type"="spruce"]
fill ~2 ~153 ~58 ~4 ~153 ~58 minecraft:snow_layer ["covered_bit"=false,"height"=0]
fill ~2 ~154 ~54 ~4 ~154 ~55 minecraft:leaves ["persistent_bit"=true,"update_bit"=false,"old_leaf_type"="spruce"]
fill ~2 ~154 ~58 ~3 ~154 ~58 minecraft:leaves ["persistent_bit"=true,"update_bit"=false,"old_leaf_type"="spruce"]
fill ~2 ~155 ~58 ~3 ~155 ~58 minecraft:snow_layer ["covered_bit"=false,"height"=0]
fill ~2 ~158 ~46 ~102 ~163 ~46 minecraft:stone ["stone_type"="stone"]
fill ~2 ~158 ~47 ~102 ~162 ~50 minecraft:stone ["stone_type"="stone"]
fill ~2 ~159 ~51 ~102 ~163 ~51 minecraft:stone ["stone_type"="stone"]
fill ~2 ~159 ~52 ~102 ~162 ~52 minecraft:stone ["stone_type"="stone"]
fill ~2 ~159 ~53 ~102 ~161 ~60 minecraft:stone ["stone_type"="stone"]
fill ~2 ~162 ~53 ~101 ~164 ~53 minecraft:stone ["stone_type"="stone"]
fill ~2 ~162 ~54 ~101 ~162 ~60 minecraft:stone ["stone_type"="stone"]
fill ~2 ~163 ~47 ~101 ~164 ~53 minecraft:stone ["stone_type"="stone"]
fill ~2 ~163 ~54 ~92 ~164 ~54 minecraft:stone ["stone_type"="stone"]
fill ~2 ~163 ~55 ~91 ~165 ~55 minecraft:stone ["stone_type"="stone"]
fill ~2 ~163 ~56 ~91 ~163 ~60 minecraft:stone ["stone_type"="stone"]
fill ~2 ~164 ~46 ~101 ~164 ~53 minecraft:stone ["stone_type"="stone"]
fill ~2 ~164 ~56 ~90 ~165 ~56 minecraft:stone ["stone_type"="stone"]
fill ~2 ~164 ~57 ~90 ~164 ~57 minecraft:stone ["stone_type"="stone"]
fill ~2 ~164 ~58 ~89 ~167 ~58 minecraft:stone ["stone_type"="stone"]
fill ~2 ~164 ~59 ~101 ~164 ~60 minecraft:stone ["stone_type"="stone"]
fill ~2 ~165 ~46 ~89 ~173 ~50 minecraft:stone ["stone_type"="stone"]
fill ~2 ~165 ~51 ~89 ~170 ~51 minecraft:stone ["stone_type"="stone"]
fill ~2 ~165 ~52 ~89 ~167 ~58 minecraft:stone ["stone_type"="stone"]
fill ~2 ~165 ~59 ~90 ~165 ~60 minecraft:stone ["stone_type"="stone"]
fill ~2 ~166 ~59 ~88 ~166 ~60 minecraft:stone ["stone_type"="stone"]
fill ~2 ~167 ~59 ~52 ~167 ~60 minecraft:stone ["stone_type"="stone"]
fill ~2 ~168 ~52 ~48 ~174 ~52 minecraft:stone ["stone_type"="stone"]
fill ~2 ~168 ~53 ~48 ~173 ~54 minecraft:stone ["stone_type"="stone"]
fill ~2 ~168 ~55 ~48 ~168 ~60 minecraft:stone ["stone_type"="stone"]
fill ~2 ~169 ~55 ~47 ~173 ~60 minecraft:stone ["stone_type"="stone"]
fill ~2 ~171 ~51 ~88 ~173 ~51 minecraft:stone ["stone_type"="stone"]
fill ~2 ~174 ~46 ~50 ~175 ~46 minecraft:stone ["stone_type"="stone"]
fill ~2 ~174 ~47 ~95 ~174 ~48 minecraft:stone ["stone_type"="stone"]
fill ~2 ~174 ~49 ~2 ~176 ~50 minecraft:dirt ["dirt_type"="normal"]
fill ~2 ~174 ~51 ~57 ~174 ~52 minecraft:stone ["stone_type"="stone"]
fill ~2 ~174 ~53 ~43 ~175 ~54 minecraft:stone ["stone_type"="stone"]
fill ~2 ~174 ~55 ~2 ~176 ~55 minecraft:dirt ["dirt_type"="normal"]
fill ~2 ~174 ~56 ~43 ~174 ~60 minecraft:stone ["stone_type"="stone"]
fill ~2 ~175 ~47 ~2 ~176 ~52 minecraft:dirt ["dirt_type"="normal"]
fill ~2 ~175 ~56 ~2 ~176 ~56 minecraft:dirt ["dirt_type"="normal"]
fill ~2 ~175 ~57 ~43 ~175 ~59 minecraft:stone ["stone_type"="stone"]
fill ~2 ~175 ~60 ~2 ~176 ~60 minecraft:dirt ["dirt_type"="normal"]
fill ~2 ~176 ~46 ~2 ~176 ~60 minecraft:dirt ["dirt_type"="normal"]
fill ~2 ~177 ~46 ~9 ~177 ~47 minecraft:grass
fill ~2 ~177 ~48 ~7 ~177 ~49 minecraft:grass
fill ~2 ~177 ~50 ~2 ~177 ~60 minecraft:grass
fill ~2 ~178 ~47 ~3 ~178 ~47 minecraft:tallgrass ["tall_grass_type"="tall"]
fill ~2 ~178 ~49 ~3 ~178 ~49 minecraft:leaves ["persistent_bit"=false,"update_bit"=false,"old_leaf_type"="jungle"]
fill ~2 ~178 ~50 ~2 ~178 ~52 minecraft:tallgrass ["tall_grass_type"="tall"]
fill ~2 ~185 ~60 ~8 ~185 ~60 minecraft:leaves ["persistent_bit"=false,"update_bit"=false,"old_leaf_type"="jungle"]
fill ~2 ~186 ~49 ~4 ~187 ~49 minecraft:leaves ["persistent_bit"=true,"update_bit"=false,"old_leaf_type"="jungle"]
fill ~2 ~186 ~50 ~2 ~189 ~50 minecraft:leaves ["persistent_bit"=true,"update_bit"=false,"old_leaf_type"="jungle"]
fill ~2 ~186 ~51 ~4 ~187 ~51 minecraft:leaves ["persistent_bit"=true,"update_bit"=false,"old_leaf_type"="jungle"]
fill ~2 ~186 ~52 ~4 ~187 ~52 minecraft:leaves ["persistent_bit"=false,"update_bit"=false,"old_leaf_type"="jungle"]
fill ~2 ~188 ~49 ~3 ~188 ~49 minecraft:leaves ["persistent_bit"=true,"update_bit"=false,"old_leaf_type"="jungle"]
fill ~2 ~189 ~52 ~9 ~189 ~54 minecraft:leaves ["persistent_bit"=false,"update_bit"=false,"old_leaf_type"="jungle"]
fill ~2 ~189 ~61 ~9 ~189 ~61 minecraft:leaves ["persistent_bit"=false,"update_bit"=false,"old_leaf_type"="jungle"]
fill ~2 ~190 ~54 ~9 ~190 ~54 minecraft:leaves ["persistent_bit"=false,"update_bit"=false,"old_leaf_type"="jungle"]
fill ~2 ~190 ~55 ~3 ~190 ~59 minecraft:leaves ["persistent_bit"=false,"update_bit"=false,"old_leaf_type"="jungle"]
fill ~2 ~191 ~56 ~3 ~191 ~57 minecraft:leaves ["persistent_bit"=false,"update_bit"=false,"old_leaf_type"="jungle"]
fill ~3 ~0 ~41 ~101 ~10 ~41 minecraft:stone ["stone_type"="stone"]
fill ~3 ~0 ~42 ~101 ~9 ~61 minecraft:stone ["stone_type"="stone"]
fill ~3 ~0 ~62 ~101 ~8 ~65 minecraft:stone ["stone_type"="stone"]
fill ~3 ~9 ~62 ~3 ~11 ~62 minecraft:dirt ["dirt_type"="normal"]
fill ~3 ~9 ~63 ~101 ~9 ~65 minecraft:stone ["stone_type"="stone"]
fill ~3 ~10 ~42 ~3 ~11 ~43 minecraft:dirt ["dirt_type"="normal"]
fill ~3 ~10 ~44 ~101 ~10 ~44 minecraft:stone ["stone_type"="stone"]
fill ~3 ~10 ~45 ~3 ~11 ~45 minecraft:dirt ["dirt_type"="normal"]
fill ~3 ~10 ~46 ~102 ~11 ~60 minecraft:stone ["stone_type"="stone"]
fill ~3 ~10 ~61 ~3 ~11 ~63 minecraft:dirt ["dirt_type"="normal"]
fill ~3 ~10 ~64 ~101 ~10 ~64 minecraft:stone ["stone_type"="stone"]
fill ~3 ~10 ~65 ~3 ~11 ~65 minecraft:dirt ["dirt_type"="normal"]
fill ~3 ~11 ~41 ~3 ~12 ~41 minecraft:dirt ["dirt_type"="normal"]
fill ~3 ~11 ~44 ~3 ~11 ~45 minecraft:dirt ["dirt_type"="normal"]
fill ~3 ~11 ~64 ~3 ~11 ~65 minecraft:dirt ["dirt_type"="normal"]
fill ~3 ~12 ~42 ~4 ~12 ~45 minecraft:grass
fill ~3 ~12 ~47 ~4 ~12 ~47 minecraft:water ["liquid_depth"=0]
fill ~3 ~12 ~48 ~3 ~12 ~51 minecraft:water ["liquid_depth"=0]
fill ~3 ~12 ~52 ~3 ~12 ~65 minecraft:grass
fill ~3 ~13 ~59 ~5 ~13 ~61 minecraft:tallgrass ["tall_grass_type"="tall"]
fill ~3 ~13 ~63 ~3 ~13 ~65 minecraft:tallgrass ["tall_grass_type"="tall"]
fill ~3 ~14 ~56 ~5 ~15 ~56 minecraft:leaves ["persistent_bit"=true,"update_bit"=false,"old_leaf_type"="oak"]
fill ~3 ~14 ~57 ~3 ~17 ~57 minecraft:leaves ["persistent_bit"=true,"update_bit"=false,"old_leaf_type"="oak"]
fill ~3 ~14 ~58 ~5 ~16 ~58 minecraft:leaves ["persistent_bit"=true,"update_bit"=false,"old_leaf_type"="oak"]
fill ~3 ~14 ~59 ~5 ~15 ~59 minecraft:leaves ["persistent_bit"=false,"update_bit"=false,"old_leaf_type"="oak"]
fill ~3 ~15 ~55 ~6 ~15 ~55 minecraft:leaves ["persistent_bit"=false,"update_bit"=false,"old_leaf_type"="oak"]
fill ~3 ~16 ~40 ~5 ~17 ~40 minecraft:leaves ["persistent_bit"=true,"update_bit"=false,"old_leaf_type"="oak"]
fill ~3 ~16 ~41 ~3 ~19 ~41 minecraft:leaves ["persistent_bit"=true,"update_bit"=false,"old_leaf_type"="oak"]
fill ~3 ~16 ~42 ~5 ~17 ~42 minecraft:leaves ["persistent_bit"=true,"update_bit"=false,"old_leaf_type"="oak"]
fill ~3 ~16 ~56 ~4 ~16 ~56 minecraft:leaves ["persistent_bit"=true,"update_bit"=false,"old_leaf_type"="oak"]
fill ~3 ~17 ~39 ~6 ~17 ~39 minecraft:leaves ["persistent_bit"=false,"update_bit"=false,"old_leaf_type"="oak"]
fill ~3 ~17 ~43 ~5 ~17 ~43 minecraft:leaves ["persistent_bit"=false,"update_bit"=false,"old_leaf_type"="oak"]
fill ~3 ~22 ~41 ~101 ~24 ~44 minecraft:stone ["stone_type"="stone"]
fill ~3 ~22 ~45 ~101 ~23 ~50 minecraft:stone ["stone_type"="stone"]
fill ~3 ~23 ~53 ~102 ~25 ~53 minecraft:stone ["stone_type"="stone"]
fill ~3 ~23 ~54 ~102 ~24 ~54 minecraft:stone ["stone_type"="stone"]
fill ~3 ~24 ~45 ~100 ~25 ~55 minecraft:stone ["stone_type"="stone"]
fill ~3 ~24 ~61 ~97 ~24 ~61 minecraft:stone ["stone_type"="stone"]
fill ~3 ~24 ~62 ~96 ~24 ~63 minecraft:stone ["stone_type"="stone"]
fill ~3 ~24 ~64 ~92 ~24 ~65 minecraft:stone ["stone_type"="stone"]
fill ~3 ~25 ~41 ~100 ~26 ~44 minecraft:stone ["stone_type"="stone"]
fill ~3 ~25 ~61 ~84 ~38 ~64 minecraft:stone ["stone_type"="stone"]
fill ~3 ~25 ~65 ~82 ~39 ~65 minecraft:stone ["stone_type"="stone"]
fill ~3 ~26 ~45 ~98 ~26 ~45 minecraft:stone ["stone_type"="stone"]
fill ~3 ~27 ~41 ~91 ~35 ~65 minecraft:stone ["stone_type"="stone"]
fill ~3 ~36 ~41 ~3 ~39 ~41 minecraft:netherrack
fill ~3 ~36 ~42 ~101 ~36 ~45 minecraft:stone ["stone_type"="stone"]
fill ~3 ~36 ~48 ~102 ~38 ~50 minecraft:stone ["stone_type"="stone"]
fill ~3 ~37 ~42 ~3 ~39 ~44 minecraft:netherrack
fill ~3 ~37 ~45 ~101 ~37 ~65 minecraft:stone ["stone_type"="stone"]
fill ~3 ~38 ~45 ~3 ~39 ~45 minecraft:netherrack
fill ~3 ~38 ~46 ~102 ~38 ~60 minecraft:stone ["stone_type"="stone"]
fill ~3 ~39 ~46 ~4 ~42 ~46 minecraft:netherrack
fill ~3 ~39 ~47 ~6 ~39 ~47 minecraft:netherrack
fill ~3 ~39 ~48 ~3 ~39 ~49 minecraft:netherrack
fill ~3 ~39 ~50 ~7 ~39 ~50 minecraft:lava ["liquid_depth"=0]
fill ~3 ~39 ~51 ~6 ~39 ~51 minecraft:lava ["liquid_depth"=0]
fill ~3 ~39 ~52 ~3 ~39 ~54 minecraft:netherrack
fill ~3 ~39 ~60 ~102 ~41 ~60 minecraft:stone ["stone_type"="stone"]
fill ~3 ~39 ~61 ~3 ~42 ~61 minecraft:dirt ["dirt_type"="normal"]
fill ~3 ~39 ~62 ~3 ~41 ~62 minecraft:dirt ["dirt_type"="normal"]
fill ~3 ~39 ~63 ~101 ~39 ~65 minecraft:stone ["stone_type"="stone"]
fill ~3 ~40 ~47 ~5 ~40 ~47 minecraft:netherrack
fill ~3 ~40 ~57 ~102 ~41 ~60 minecraft:stone ["stone_type"="stone"]
fill ~3 ~40 ~63 ~3 ~41 ~63 minecraft:dirt ["dirt_type"="normal"]
fill ~3 ~40 ~64 ~101 ~40 ~64 minecraft:stone ["stone_type"="stone"]
fill ~3 ~40 ~65 ~3 ~41 ~65 minecraft:dirt ["dirt_type"="normal"]
fill ~3 ~41 ~47 ~3 ~42 ~47 minecraft:netherrack
fill ~3 ~41 ~56 ~3 ~41 ~60 minecraft:stone ["stone_type"="stone"]
fill ~3 ~41 ~64 ~3 ~41 ~65 minecraft:dirt ["dirt_type"="normal"]
fill ~3 ~42 ~58 ~3 ~42 ~60 minecraft:stone ["stone_type"="stone"]
fill ~3 ~42 ~62 ~8 ~42 ~63 minecraft:grass
fill ~3 ~42 ~64 ~5 ~42 ~65 minecraft:grass
fill ~3 ~43 ~58 ~3 ~46 ~58 minecraft:wood ["stripped_bit"=false,"pillar_axis"="y","wood_type"="oak"]
fill ~3 ~43 ~59 ~3 ~45 ~60 minecraft:planks ["wood_type"="oak"]
fill ~3 ~43 ~61 ~3 ~46 ~61 minecraft:wood ["stripped_bit"=false,"pillar_axis"="y","wood_type"="oak"]
fill ~3 ~46 ~59 ~3 ~46 ~61 minecraft:wood ["stripped_bit"=false,"pillar_axis"="y","wood_type"="oak"]
fill ~3 ~51 ~41 ~101 ~60 ~42 minecraft:stone ["stone_type"="stone"]
fill ~3 ~51 ~43 ~101 ~59 ~44 minecraft:stone ["stone_type"="stone"]
fill ~3 ~52 ~45 ~101 ~60 ~45 minecraft:stone ["stone_type"="stone"]
fill ~3 ~53 ~61 ~101 ~56 ~61 minecraft:stone ["stone_type"="stone"]
fill ~3 ~54 ~62 ~101 ~57 ~63 minecraft:stone ["stone_type"="stone"]
fill ~3 ~54 ~64 ~101 ~55 ~65 minecraft:stone ["stone_type"="stone"]
fill ~3 ~56 ~64 ~89 ~61 ~64 minecraft:stone ["stone_type"="stone"]
fill ~3 ~56 ~65 ~88 ~61 ~65 minecraft:stone ["stone_type"="stone"]
fill ~3 ~57 ~61 ~100 ~57 ~63 minecraft:stone ["stone_type"="stone"]
fill ~3 ~58 ~61 ~92 ~58 ~63 minecraft:stone ["stone_type"="stone"]
fill ~3 ~59 ~61 ~90 ~77 ~61 minecraft:stone ["stone_type"="stone"]
fill ~3 ~59 ~62 ~90 ~61 ~62 minecraft:stone ["stone_type"="stone"]
fill ~3 ~59 ~63 ~90 ~60 ~63 minecraft:stone ["stone_type"="stone"]
fill ~3 ~60 ~43 ~100 ~60 ~43 minecraft:stone ["stone_type"="stone"]
fill ~3 ~60 ~44 ~98 ~60 ~46 minecraft:stone ["stone_type"="stone"]
fill ~3 ~61 ~41 ~93 ~61 ~54 minecraft:stone ["stone_type"="stone"]
fill ~3 ~61 ~63 ~28 ~76 ~65 minecraft:stone ["stone_type"="stone"]
fill ~3 ~62 ~41 ~92 ~70 ~57 minecraft:stone ["stone_type"="stone"]
fill ~3 ~62 ~62 ~28 ~77 ~62 minecraft:stone ["stone_type"="stone"]
fill ~3 ~71 ~41 ~91 ~75 ~43 minecraft:stone ["stone_type"="stone"]
fill ~3 ~71 ~44 ~94 ~74 ~55 minecraft:stone ["stone_type"="stone"]
fill ~3 ~75 ~44 ~4 ~76 ~44 minecraft:stone ["stone_type"="stone"]
fill ~3 ~75 ~45 ~3 ~76 ~45 minecraft:stone ["stone_type"="stone"]
fill ~3 ~75 ~46 ~6 ~75 ~46 minecraft:flowing_water ["liquid_depth"=8]
fill ~3 ~75 ~47 ~3 ~76 ~65 minecraft:stone ["stone_type"="stone"]
fill ~3 ~76 ~41 ~3 ~76 ~45 minecraft:stone ["stone_type"="stone"]
fill ~3 ~76 ~46 ~7 ~76 ~46 minecraft:water ["liquid_depth"=0]
fill ~3 ~77 ~49 ~3 ~77 ~51 minecraft:stone ["stone_type"="stone"]
fill ~3 ~77 ~52 ~7 ~77 ~54 minecraft:water ["liquid_depth"=0]
fill ~3 ~77 ~55 ~6 ~77 ~55 minecraft:water ["liquid_depth"=0]
fill ~3 ~77 ~57 ~5 ~77 ~57 minecraft:stone ["stone_type"="andesite"]
fill ~3 ~77 ~58 ~4 ~77 ~58 minecraft:stone ["stone_type"="andesite"]
fill ~3 ~77 ~59 ~3 ~77 ~62 minecraft:stone ["stone_type"="stone"]
fill ~3 ~77 ~63 ~3 ~79 ~64 minecraft:magma
fill ~3 ~77 ~65 ~101 ~77 ~65 minecraft:stone ["stone_type"="stone"]
fill ~3 ~78 ~61 ~3 ~79 ~65 minecraft:magma
fill ~3 ~87 ~41 ~101 ~87 ~41 minecraft:stone ["stone_type"="stone"]
fill ~3 ~87 ~42 ~100 ~91 ~48 minecraft:stone ["stone_type"="stone"]
fill ~3 ~87 ~56 ~3 ~114 ~56 minecraft:stone ["stone_type"="stone"]
fill ~3 ~88 ~41 ~100 ~91 ~53 minecraft:stone ["stone_type"="stone"]
fill ~3 ~88 ~58 ~102 ~89 ~58 minecraft:stone ["stone_type"="stone"]
fill ~3 ~89 ~61 ~100 ~89 ~64 minecraft:stone ["stone_type"="stone"]
fill ~3 ~89 ~65 ~8 ~114 ~65 minecraft:stone ["stone_type"="stone"]
fill ~3 ~90 ~61 ~88 ~113 ~61 minecraft:stone ["stone_type"="stone"]
fill ~3 ~90 ~62 ~88 ~112 ~65 minecraft:stone ["stone_type"="stone"]
fill ~3 ~92 ~41 ~92 ~108 ~41 minecraft:stone ["stone_type"="stone"]
fill ~3 ~92 ~42 ~92 ~107 ~43 minecraft:stone ["stone_type"="stone"]
fill ~3 ~92 ~44 ~92 ~106 ~45 minecraft:stone ["stone_type"="stone"]
fill ~3 ~107 ~44 ~3 ~109 ~44 minecraft:dirt ["dirt_type"="normal"]
fill ~3 ~107 ~45 ~101 ~107 ~65 minecraft:stone ["stone_type"="stone"]
fill ~3 ~108 ~42 ~3 ~109 ~42 minecraft:dirt ["dirt_type"="normal"]
fill ~3 ~108 ~43 ~101 ~108 ~43 minecraft:stone ["stone_type"="stone"]
fill ~3 ~108 ~45 ~3 ~109 ~45 minecraft:dirt ["dirt_type"="normal"]
fill ~3 ~108 ~47 ~102 ~109 ~60 minecraft:stone ["stone_type"="stone"]
fill ~3 ~109 ~41 ~3 ~109 ~45 minecraft:dirt ["dirt_type"="normal"]
fill ~3 ~109 ~46 ~102 ~109 ~60 minecraft:stone ["stone_type"="stone"]
fill ~3 ~110 ~41 ~5 ~110 ~42 minecraft:grass
fill ~3 ~110 ~43 ~4 ~110 ~47 minecraft:grass
fill ~3 ~110 ~48 ~4 ~110 ~48 minecraft:dirt ["dirt_type"="normal"]
fill ~3 ~110 ~50 ~7 ~110 ~50 minecraft:stained_hardened_clay ["color"="red"]
fill ~3 ~110 ~51 ~6 ~110 ~51 minecraft:stained_hardened_clay ["color"="red"]
fill ~3 ~110 ~52 ~3 ~110 ~65 minecraft:stone ["stone_type"="stone"]
fill ~3 ~111 ~43 ~3 ~111 ~44 minecraft:fence ["wood_type"="oak"]
fill ~3 ~111 ~48 ~4 ~111 ~48 minecraft:stained_hardened_clay ["color"="red"]
fill ~3 ~111 ~51 ~5 ~111 ~51 minecraft:carpet ["color"="red"]
fill ~3 ~111 ~53 ~3 ~112 ~53 minecraft:stained_hardened_clay ["color"="red"]
fill ~3 ~111 ~54 ~102 ~112 ~60 minecraft:stone ["stone_type"="stone"]
fill ~3 ~113 ~48 ~6 ~113 ~52 minecraft:stained_hardened_clay ["color"="red"]
fill ~3 ~113 ~54 ~3 ~115 ~54 minecraft:stone ["stone_type"="stone"]
fill ~3 ~113 ~55 ~102 ~114 ~60 minecraft:stone ["stone_type"="stone"]
fill ~3 ~113 ~62 ~3 ~114 ~63 minecraft:dirt ["dirt_type"="normal"]
fill ~3 ~113 ~64 ~101 ~113 ~65 minecraft:stone ["stone_type"="stone"]
fill ~3 ~114 ~49 ~8 ~114 ~49 minecraft:stained_hardened_clay ["color"="orange"]
fill ~3 ~114 ~50 ~4 ~115 ~50 minecraft:stained_hardened_clay ["color"="orange"]
fill ~3 ~114 ~51 ~3 ~115 ~53 minecraft:stained_hardened_clay ["color"="orange"]
fill ~3 ~114 ~61 ~3 ~114 ~64 minecraft:dirt ["dirt_type"="normal"]
fill ~3 ~115 ~49 ~4 ~115 ~50 minecraft:stained_hardened_clay ["color"="orange"]
fill ~3 ~115 ~55 ~10 ~115 ~58 minecraft:grass
fill ~3 ~115 ~60 ~4 ~115 ~65 minecraft:grass
fill ~3 ~116 ~49 ~3 ~116 ~54 minecraft:stone_block_slab4 ["top_slot_bit"=false,"stone_slab_type_4"="stone"]
fill ~3 ~116 ~55 ~3 ~116 ~57 minecraft:tallgrass ["tall_grass_type"="tall"]
fill ~3 ~116 ~59 ~3 ~120 ~59 minecraft:log ["pillar_axis"="y","old_log_type"="oak"]
fill ~3 ~116 ~62 ~4 ~116 ~65 minecraft:tallgrass ["tall_grass_type"="tall"]
fill ~3 ~120 ~58 ~4 ~120 ~58 minecraft:leaves ["persistent_bit"=true,"update_bit"=false,"old_leaf_type"="oak"]
fill ~3 ~120 ~60 ~3 ~121 ~60 minecraft:leaves ["persistent_bit"=true,"update_bit"=false,"old_leaf_type"="oak"]
fill ~3 ~121 ~58 ~3 ~121 ~60 minecraft:leaves ["persistent_bit"=true,"update_bit"=false,"old_leaf_type"="oak"]
fill ~3 ~122 ~41 ~101 ~129 ~41 minecraft:stone ["stone_type"="stone"]
fill ~3 ~122 ~42 ~101 ~128 ~42 minecraft:stone ["stone_type"="stone"]
fill ~3 ~122 ~43 ~101 ~127 ~45 minecraft:stone ["stone_type"="stone"]
fill ~3 ~123 ~48 ~102 ~128 ~48 minecraft:stone ["stone_type"="stone"]
fill ~3 ~124 ~61 ~101 ~129 ~61 minecraft:stone ["stone_type"="stone"]
fill ~3 ~125 ~62 ~101 ~130 ~62 minecraft:stone ["stone_type"="stone"]
fill ~3 ~125 ~63 ~101 ~129 ~63 minecraft:stone ["stone_type"="stone"]
fill ~3 ~125 ~64 ~101 ~128 ~65 minecraft:stone ["stone_type"="stone"]
fill ~3 ~128 ~43 ~100 ~130 ~65 minecraft:stone ["stone_type"="stone"]
fill ~3 ~129 ~42 ~100 ~130 ~65 minecraft:stone ["stone_type"="stone"]
fill ~3 ~130 ~41 ~100 ~130 ~65 minecraft:stone ["stone_type"="stone"]
fill ~3 ~131 ~41 ~97 ~133 ~41 minecraft:stone ["stone_type"="stone"]
fill ~3 ~131 ~42 ~95 ~132 ~44 minecraft:stone ["stone_type"="stone"]
fill ~3 ~131 ~45 ~90 ~143 ~65 minecraft:stone ["stone_type"="stone"]
fill ~3 ~133 ~42 ~94 ~134 ~63 minecraft:stone ["stone_type"="stone"]
fill ~3 ~134 ~41 ~95 ~134 ~41 minecraft:stone ["stone_type"="stone"]
fill ~3 ~135 ~41 ~93 ~142 ~65 minecraft:stone ["stone_type"="stone"]
fill ~3 ~143 ~41 ~3 ~144 ~41 minecraft:log ["pillar_axis"="y","old_log_type"="spruce"]
fill ~3 ~143 ~42 ~96 ~143 ~43 minecraft:stone ["stone_type"="stone"]
fill ~3 ~143 ~44 ~3 ~144 ~44 minecraft:log ["pillar_axis"="y","old_log_type"="spruce"]
fill ~3 ~144 ~42 ~3 ~144 ~45 minecraft:log ["pillar_axis"="y","old_log_type"="spruce"]
fill ~3 ~144 ~55 ~102 ~148 ~57 minecraft:stone ["stone_type"="stone"]
fill ~3 ~144 ~61 ~12 ~145 ~65 minecraft:stone ["stone_type"="stone"]
fill ~3 ~145 ~41 ~15 ~145 ~43 minecraft:wood ["stripped_bit"=false,"pillar_axis"="y","wood_type"="spruce"]
fill ~3 ~145 ~44 ~4 ~145 ~45 minecraft:slime
fill ~3 ~145 ~51 ~5 ~147 ~60 minecraft:stone ["stone_type"="stone"]
fill ~3 ~146 ~41 ~4 ~146 ~41 minecraft:fence ["wood_type"="oak"]
fill ~3 ~146 ~50 ~102 ~147 ~58 minecraft:stone ["stone_type"="stone"]
fill ~3 ~146 ~61 ~3 ~148 ~61 minecraft:dirt ["dirt_type"="normal"]
fill ~3 ~146 ~62 ~12 ~146 ~64 minecraft:stone ["stone_type"="stone"]
fill ~3 ~146 ~65 ~3 ~148 ~65 minecraft:dirt ["dirt_type"="normal"]
fill ~3 ~147 ~48 ~3 ~147 ~60 minecraft:stone ["stone_type"="stone"]
fill ~3 ~147 ~62 ~3 ~148 ~62 minecraft:dirt ["dirt_type"="normal"]
fill ~3 ~147 ~63 ~11 ~147 ~63 minecraft:stone ["stone_type"="stone"]
fill ~3 ~147 ~64 ~3 ~148 ~65 minecraft:dirt ["dirt_type"="normal"]
fill ~3 ~148 ~48 ~4 ~148 ~48 minecraft:snow
fill ~3 ~148 ~52 ~102 ~148 ~57 minecraft:stone ["stone_type"="stone"]
fill ~3 ~148 ~58 ~17 ~148 ~58 minecraft:stone ["stone_type"="stone"]
fill ~3 ~148 ~59 ~15 ~148 ~59 minecraft:stone ["stone_type"="stone"]
fill ~3 ~148 ~60 ~13 ~148 ~60 minecraft:stone ["stone_type"="stone"]
fill ~3 ~148 ~63 ~3 ~148 ~65 minecraft:dirt ["dirt_type"="normal"]
fill ~3 ~149 ~54 ~6 ~149 ~54 minecraft:packed_ice
fill ~3 ~149 ~57 ~5 ~149 ~57 minecraft:grass
fill ~3 ~149 ~58 ~4 ~149 ~59 minecraft:grass
fill ~3 ~149 ~60 ~3 ~149 ~65 minecraft:grass
fill ~3 ~150 ~56 ~3 ~156 ~56 minecraft:log ["pillar_axis"="y","old_log_type"="spruce"]
fill ~3 ~150 ~57 ~5 ~150 ~57 minecraft:snow_layer ["covered_bit"=false,"height"=0]
fill ~3 ~150 ~58 ~4 ~150 ~59 minecraft:snow_layer ["covered_bit"=false,"height"=0]
fill ~3 ~150 ~64 ~5 ~150 ~64 minecraft:snow_layer ["covered_bit"=false,"height"=0]
fill ~3 ~152 ~58 ~4 ~152 ~58 minecraft:leaves ["persistent_bit"=true,"update_bit"=false,"old_leaf_type"="spruce"]
fill ~3 ~153 ~55 ~3 ~154 ~55 minecraft:leaves ["persistent_bit"=true,"update_bit"=false,"old_leaf_type"="spruce"]
fill ~3 ~153 ~57 ~3 ~154 ~57 minecraft:leaves ["persistent_bit"=true,"update_bit"=false,"old_leaf_type"="spruce"]
fill ~3 ~155 ~57 ~4 ~155 ~57 minecraft:snow_layer ["covered_bit"=false,"height"=0]
fill ~3 ~157 ~41 ~101 ~163 ~41 minecraft:stone ["stone_type"="stone"]
fill ~3 ~157 ~42 ~101 ~161 ~48 minecraft:stone ["stone_type"="stone"]
fill ~3 ~158 ~51 ~102 ~163 ~51 minecraft:stone ["stone_type"="stone"]
fill ~3 ~159 ~61 ~101 ~161 ~62 minecraft:stone ["stone_type"="stone"]
fill ~3 ~159 ~63 ~4 ~173 ~63 minecraft:stone ["stone_type"="stone"]
fill ~3 ~160 ~64 ~101 ~163 ~64 minecraft:stone ["stone_type"="stone"]
fill ~3 ~160 ~65 ~101 ~161 ~65 minecraft:stone ["stone_type"="stone"]
fill ~3 ~162 ~42 ~100 ~163 ~53 minecraft:stone ["stone_type"="stone"]
fill ~3 ~162 ~61 ~100 ~164 ~65 minecraft:stone ["stone_type"="stone"]
fill ~3 ~164 ~41 ~96 ~164 ~53 minecraft:stone ["stone_type"="stone"]
fill ~3 ~165 ~41 ~89 ~173 ~50 minecraft:stone ["stone_type"="stone"]
fill ~3 ~165 ~61 ~89 ~165 ~64 minecraft:stone ["stone_type"="stone"]
fill ~3 ~165 ~65 ~87 ~167 ~65 minecraft:stone ["stone_type"="stone"]
fill ~3 ~166 ~61 ~88 ~166 ~64 minecraft:stone ["stone_type"="stone"]
fill ~3 ~167 ~61 ~87 ~167 ~65 minecraft:stone ["stone_type"="stone"]
fill ~3 ~168 ~61 ~48 ~174 ~62 minecraft:stone ["stone_type"="stone"]
fill ~3 ~168 ~64 ~48 ~174 ~65 minecraft:stone ["stone_type"="stone"]
fill ~3 ~174 ~41 ~3 ~176 ~41 minecraft:dirt ["dirt_type"="normal"]
fill ~3 ~174 ~42 ~92 ~174 ~45 minecraft:stone ["stone_type"="stone"]
fill ~3 ~174 ~49 ~95 ~174 ~50 minecraft:stone ["stone_type"="stone"]
fill ~3 ~174 ~55 ~44 ~174 ~55 minecraft:stone ["stone_type"="stone"]
fill ~3 ~174 ~63 ~3 ~176 ~63 minecraft:dirt ["dirt_type"="normal"]
fill ~3 ~175 ~42 ~3 ~176 ~43 minecraft:dirt ["dirt_type"="normal"]
fill ~3 ~175 ~44 ~94 ~175 ~48 minecraft:stone ["stone_type"="stone"]
fill ~3 ~175 ~49 ~57 ~176 ~49 minecraft:stone ["stone_type"="stone"]
fill ~3 ~175 ~50 ~57 ~175 ~50 minecraft:stone ["stone_type"="stone"]
fill ~3 ~175 ~51 ~43 ~176 ~54 minecraft:stone ["stone_type"="stone"]
fill ~3 ~175 ~55 ~42 ~175 ~60 minecraft:stone ["stone_type"="stone"]
fill ~3 ~175 ~61 ~3 ~176 ~64 minecraft:dirt ["dirt_type"="normal"]
fill ~3 ~175 ~65 ~51 ~175 ~65 minecraft:stone ["stone_type"="stone"]
fill ~3 ~176 ~44 ~3 ~176 ~45 minecraft:dirt ["dirt_type"="normal"]
fill ~3 ~176 ~46 ~97 ~176 ~47 minecraft:stone ["stone_type"="stone"]
fill ~3 ~176 ~48 ~57 ~176 ~49 minecraft:stone ["stone_type"="stone"]
fill ~3 ~176 ~50 ~43 ~176 ~54 minecraft:stone ["stone_type"="stone"]
fill ~3 ~176 ~55 ~41 ~176 ~60 minecraft:stone ["stone_type"="stone"]
fill ~3 ~177 ~41 ~12 ~177 ~43 minecraft:grass
fill ~3 ~177 ~44 ~11 ~177 ~45 minecraft:grass
fill ~3 ~177 ~51 ~6 ~177 ~55 minecraft:grass
fill ~3 ~177 ~56 ~4 ~177 ~65 minecraft:grass
fill ~3 ~178 ~44 ~4 ~178 ~44 minecraft:tallgrass ["tall_grass_type"="tall"]
fill ~3 ~178 ~48 ~4 ~178 ~48 minecraft:leaves ["persistent_bit"=false,"update_bit"=false,"old_leaf_type"="jungle"]
fill ~3 ~178 ~50 ~3 ~188 ~50 minecraft:log ["pillar_axis"="y","old_log_type"="jungle"]
fill ~3 ~178 ~60 ~4 ~178 ~60 minecraft:tallgrass ["tall_grass_type"="tall"]
fill ~3 ~178 ~61 ~3 ~178 ~65 minecraft:tallgrass ["tall_grass_type"="tall"]
fill ~3 ~185 ~58 ~3 ~185 ~62 minecraft:leaves ["persistent_bit"=false,"update_bit"=false,"old_leaf_type"="jungle"]
fill ~3 ~186 ~60 ~4 ~186 ~60 minecraft:leaves ["persistent_bit"=false,"update_bit"=false,"old_leaf_type"="jungle"]
fill ~3 ~188 ~51 ~3 ~189 ~51 minecraft:leaves ["persistent_bit"=true,"update_bit"=false,"old_leaf_type"="jungle"]
fill ~3 ~189 ~49 ~3 ~189 ~51 minecraft:leaves ["persistent_bit"=true,"update_bit"=false,"old_leaf_type"="jungle"]
fill ~3 ~190 ~53 ~8 ~190 ~54 minecraft:leaves ["persistent_bit"=false,"update_bit"=false,"old_leaf_type"="jungle"]
fill ~3 ~190 ~60 ~8 ~190 ~60 minecraft:leaves ["persistent_bit"=false,"update_bit"=false,"old_leaf_type"="jungle"]
fill ~3 ~191 ~54 ~8 ~191 ~54 minecraft:leaves ["persistent_bit"=false,"update_bit"=false,"old_leaf_type"="jungle"]
fill ~3 ~191 ~55 ~3 ~191 ~59 minecraft:leaves ["persistent_bit"=false,"update_bit"=false,"old_leaf_type"="jungle"]
fill ~4 ~0 ~38 ~100 ~10 ~39 minecraft:stone ["stone_type"="stone"]
fill ~4 ~0 ~40 ~100 ~9 ~68 minecraft:stone ["stone_type"="stone"]
fill ~4 ~10 ~40 ~5 ~10 ~40 minecraft:dirt ["dirt_type"="normal"]
fill ~4 ~10 ~42 ~101 ~11 ~65 minecraft:stone ["stone_type"="stone"]
fill ~4 ~10 ~66 ~100 ~10 ~68 minecraft:stone ["stone_type"="stone"]
fill ~4 ~11 ~38 ~6 ~11 ~39 minecraft:stone ["stone_type"="stone"]
fill ~4 ~11 ~40 ~4 ~12 ~40 minecraft:dirt ["dirt_type"="normal"]
fill ~4 ~11 ~41 ~101 ~11 ~65 minecraft:stone ["stone_type"="stone"]
fill ~4 ~11 ~67 ~100 ~14 ~68 minecraft:stone ["stone_type"="stone"]
fill ~4 ~12 ~41 ~5 ~12 ~41 minecraft:dirt ["dirt_type"="normal"]
fill ~4 ~12 ~46 ~6 ~12 ~46 minecraft:water ["liquid_depth"=0]
fill ~4 ~12 ~48 ~11 ~12 ~48 minecraft:grass
fill ~4 ~12 ~49 ~5 ~12 ~49 minecraft:grass
fill ~4 ~12 ~50 ~4 ~12 ~53 minecraft:water ["liquid_depth"=0]
fill ~4 ~12 ~54 ~5 ~12 ~56 minecraft:grass
fill ~4 ~12 ~58 ~6 ~12 ~62 minecraft:grass
fill ~4 ~12 ~63 ~5 ~12 ~65 minecraft:grass
fill ~4 ~13 ~39 ~4 ~13 ~40 minecraft:grass
fill ~4 ~13 ~41 ~4 ~18 ~41 minecraft:log ["pillar_axis"="y","old_log_type"="oak"]
fill ~4 ~13 ~43 ~6 ~13 ~44 minecraft:tallgrass ["tall_grass_type"="tall"]
fill ~4 ~13 ~54 ~5 ~13 ~55 minecraft:tallgrass ["tall_grass_type"="tall"]
fill ~4 ~13 ~57 ~4 ~16 ~57 minecraft:log ["pillar_axis"="y","old_log_type"="oak"]
fill ~4 ~13 ~58 ~4 ~13 ~62 minecraft:tallgrass ["tall_grass_type"="tall"]
fill ~4 ~14 ~48 ~7 ~15 ~48 minecraft:leaves ["persistent_bit"=true,"update_bit"=false,"old_leaf_type"="oak"]
fill ~4 ~14 ~49 ~4 ~15 ~51 minecraft:leaves ["persistent_bit"=false,"update_bit"=false,"old_leaf_type"="oak"]
fill ~4 ~15 ~47 ~5 ~15 ~48 minecraft:leaves ["persistent_bit"=true,"update_bit"=false,"old_leaf_type"="oak"]
fill ~4 ~15 ~67 ~5 ~15 ~67 minecraft:stone ["stone_type"="stone"]
fill ~4 ~17 ~56 ~4 ~17 ~58 minecraft:leaves ["persistent_bit"=true,"update_bit"=false,"old_leaf_type"="oak"]
fill ~4 ~18 ~40 ~5 ~18 ~40 minecraft:leaves ["persistent_bit"=true,"update_bit"=false,"old_leaf_type"="oak"]
fill ~4 ~18 ~42 ~5 ~18 ~42 minecraft:leaves ["persistent_bit"=true,"update_bit"=false,"old_leaf_type"="oak"]
fill ~4 ~19 ~40 ~4 ~19 ~42 minecraft:leaves ["persistent_bit"=true,"update_bit"=false,"old_leaf_type"="oak"]
fill ~4 ~22 ~38 ~5 ~36 ~38 minecraft:stone ["stone_type"="stone"]
fill ~4 ~22 ~39 ~4 ~37 ~39 minecraft:stone ["stone_type"="stone"]
fill ~4 ~22 ~40 ~5 ~36 ~51 minecraft:stone ["stone_type"="stone"]
fill ~4 ~23 ~55 ~102 ~25 ~55 minecraft:stone ["stone_type"="stone"]
fill ~4 ~23 ~56 ~102 ~24 ~57 minecraft:stone ["stone_type"="stone"]
fill ~4 ~23 ~58 ~102 ~23 ~58 minecraft:stone ["stone_type"="stone"]
fill ~4 ~24 ~66 ~92 ~38 ~66 minecraft:stone ["stone_type"="stone"]
fill ~4 ~24 ~67 ~96 ~24 ~68 minecraft:stone ["stone_type"="stone"]
fill ~4 ~25 ~67 ~92 ~27 ~67 minecraft:stone ["stone_type"="stone"]
fill ~4 ~25 ~68 ~91 ~29 ~68 minecraft:stone ["stone_type"="stone"]
fill ~4 ~28 ~67 ~91 ~39 ~67 minecraft:stone ["stone_type"="stone"]
fill ~4 ~30 ~68 ~90 ~39 ~68 minecraft:stone ["stone_type"="stone"]
fill ~4 ~37 ~38 ~4 ~39 ~38 minecraft:netherrack
fill ~4 ~37 ~40 ~4 ~39 ~40 minecraft:netherrack
fill ~4 ~37 ~41 ~101 ~38 ~65 minecraft:stone ["stone_type"="stone"]
fill ~4 ~38 ~39 ~4 ~39 ~40 minecraft:netherrack
fill ~4 ~39 ~41 ~5 ~39 ~41 minecraft:netherrack
fill ~4 ~39 ~42 ~4 ~43 ~42 minecraft:netherrack
fill ~4 ~39 ~44 ~7 ~39 ~44 minecraft:lava ["liquid_depth"=0]
fill ~4 ~39 ~45 ~16 ~39 ~45 minecraft:netherrack
fill ~4 ~39 ~48 ~4 ~39 ~53 minecraft:lava ["liquid_depth"=0]
fill ~4 ~39 ~54 ~5 ~39 ~54 minecraft:netherrack
fill ~4 ~39 ~61 ~101 ~42 ~61 minecraft:stone ["stone_type"="stone"]
fill ~4 ~39 ~62 ~101 ~41 ~65 minecraft:stone ["stone_type"="stone"]
fill ~4 ~39 ~66 ~4 ~41 ~66 minecraft:dirt ["dirt_type"="normal"]
fill ~4 ~40 ~41 ~4 ~44 ~41 minecraft:netherrack
fill ~4 ~40 ~67 ~4 ~41 ~68 minecraft:dirt ["dirt_type"="normal"]
fill ~4 ~41 ~45 ~6 ~41 ~46 minecraft:netherrack
fill ~4 ~42 ~45 ~5 ~42 ~46 minecraft:netherrack
fill ~4 ~42 ~58 ~4 ~42 ~60 minecraft:planks ["wood_type"="oak"]
fill ~4 ~42 ~66 ~11 ~42 ~66 minecraft:grass
fill ~4 ~42 ~67 ~4 ~42 ~68 minecraft:grass
fill ~4 ~43 ~61 ~5 ~45 ~61 minecraft:planks ["wood_type"="oak"]
fill ~4 ~44 ~40 ~4 ~44 ~41 minecraft:netherrack
fill ~4 ~45 ~58 ~5 ~45 ~58 minecraft:planks ["wood_type"="oak"]
fill ~4 ~46 ~58 ~6 ~46 ~58 minecraft:wood ["stripped_bit"=false,"pillar_axis"="y","wood_type"="oak"]
fill ~4 ~46 ~59 ~5 ~46 ~60 minecraft:planks ["wood_type"="oak"]
fill ~4 ~46 ~61 ~6 ~46 ~61 minecraft:wood ["stripped_bit"=false,"pillar_axis"="y","wood_type"="oak"]
fill ~4 ~50 ~38 ~100 ~60 ~38 minecraft:stone ["stone_type"="stone"]
fill ~4 ~50 ~39 ~100 ~59 ~39 minecraft:stone ["stone_type"="stone"]
fill ~4 ~51 ~40 ~100 ~59 ~46 minecraft:stone ["stone_type"="stone"]
fill ~4 ~51 ~47 ~102 ~57 ~48 minecraft:stone ["stone_type"="stone"]
fill ~4 ~51 ~49 ~102 ~56 ~49 minecraft:stone ["stone_type"="stone"]
fill ~4 ~51 ~50 ~6 ~75 ~50 minecraft:stone ["stone_type"="stone"]
fill ~4 ~52 ~58 ~102 ~57 ~58 minecraft:stone ["stone_type"="stone"]
fill ~4 ~54 ~66 ~100 ~55 ~68 minecraft:stone ["stone_type"="stone"]
fill ~4 ~56 ~66 ~87 ~61 ~66 minecraft:stone ["stone_type"="stone"]
fill ~4 ~56 ~67 ~74 ~61 ~68 minecraft:stone ["stone_type"="stone"]
fill ~4 ~60 ~39 ~99 ~60 ~43 minecraft:stone ["stone_type"="stone"]
fill ~4 ~61 ~38 ~94 ~61 ~38 minecraft:stone ["stone_type"="stone"]
fill ~4 ~61 ~39 ~93 ~61 ~54 minecraft:stone ["stone_type"="stone"]
fill ~4 ~62 ~38 ~93 ~63 ~38 minecraft:stone ["stone_type"="stone"]
fill ~4 ~62 ~39 ~92 ~63 ~57 minecraft:stone ["stone_type"="stone"]
fill ~4 ~62 ~66 ~28 ~76 ~68 minecraft:stone ["stone_type"="stone"]
fill ~4 ~64 ~38 ~81 ~73 ~66 minecraft:stone ["stone_type"="stone"]
fill ~4 ~74 ~38 ~9 ~74 ~68 minecraft:stone ["stone_type"="stone"]
fill ~4 ~75 ~38 ~7 ~75 ~43 minecraft:stone ["stone_type"="stone"]
fill ~4 ~75 ~45 ~6 ~75 ~46 minecraft:flowing_water ["liquid_depth"=8]
fill ~4 ~75 ~47 ~5 ~75 ~47 minecraft:flowing_water ["liquid_depth"=8]
fill ~4 ~75 ~48 ~102 ~75 ~60 minecraft:stone ["stone_type"="stone"]
fill ~4 ~76 ~38 ~6 ~76 ~40 minecraft:stone ["stone_type"="stone"]
fill ~4 ~76 ~42 ~101 ~76 ~43 minecraft:stone ["stone_type"="stone"]
fill ~4 ~76 ~45 ~7 ~76 ~48 minecraft:water ["liquid_depth"=0]
fill ~4 ~76 ~49 ~102 ~76 ~49 minecraft:stone ["stone_type"="stone"]
fill ~4 ~76 ~50 ~4 ~76 ~52 minecraft:stone ["stone_type"="stone"]
fill ~4 ~76 ~53 ~6 ~76 ~53 minecraft:flowing_water ["liquid_depth"=8]
fill ~4 ~76 ~54 ~4 ~76 ~68 minecraft:stone ["stone_type"="stone"]
fill ~4 ~77 ~49 ~6 ~77 ~55 minecraft:water ["liquid_depth"=0]
fill ~4 ~77 ~56 ~5 ~77 ~56 minecraft:water ["liquid_depth"=0]
fill ~4 ~77 ~63 ~101 ~78 ~65 minecraft:stone ["stone_type"="stone"]
fill ~4 ~77 ~66 ~4 ~79 ~66 minecraft:magma
fill ~4 ~77 ~67 ~100 ~77 ~67 minecraft:stone ["stone_type"="stone"]
fill ~4 ~77 ~68 ~4 ~79 ~68 minecraft:magma
fill ~4 ~78 ~61 ~101 ~78 ~65 minecraft:stone ["stone_type"="stone"]
fill ~4 ~78 ~67 ~4 ~79 ~68 minecraft:magma
fill ~4 ~79 ~61 ~10 ~79 ~62 minecraft:lava ["liquid_depth"=0]
fill ~4 ~79 ~63 ~5 ~79 ~65 minecraft:lava ["liquid_depth"=0]
fill ~4 ~86 ~38 ~4 ~108 ~38 minecraft:stone ["stone_type"="stone"]
fill ~4 ~87 ~39 ~100 ~87 ~48 minecraft:stone ["stone_type"="stone"]
fill ~4 ~87 ~68 ~6 ~112 ~68 minecraft:stone ["stone_type"="stone"]
fill ~4 ~88 ~39 ~99 ~91 ~53 minecraft:stone ["stone_type"="stone"]
fill ~4 ~88 ~65 ~4 ~114 ~66 minecraft:stone ["stone_type"="stone"]
fill ~4 ~88 ~67 ~6 ~113 ~67 minecraft:stone ["stone_type"="stone"]
fill ~4 ~92 ~39 ~92 ~105 ~45 minecraft:stone ["stone_type"="stone"]
fill ~4 ~106 ~39 ~12 ~107 ~39 minecraft:stone ["stone_type"="stone"]
fill ~4 ~106 ~40 ~100 ~106 ~68 minecraft:stone ["stone_type"="stone"]
fill ~4 ~107 ~40 ~4 ~109 ~40 minecraft:dirt ["dirt_type"="normal"]
fill ~4 ~107 ~44 ~101 ~109 ~65 minecraft:stone ["stone_type"="stone"]
fill ~4 ~108 ~39 ~4 ~109 ~40 minecraft:dirt ["dirt_type"="normal"]
fill ~4 ~108 ~42 ~101 ~109 ~65 minecraft:stone ["stone_type"="stone"]
fill ~4 ~109 ~38 ~4 ~109 ~40 minecraft:dirt ["dirt_type"="normal"]
fill ~4 ~109 ~41 ~101 ~109 ~65 minecraft:stone ["stone_type"="stone"]
fill ~4 ~110 ~38 ~11 ~110 ~38 minecraft:grass
fill ~4 ~110 ~39 ~6 ~110 ~39 minecraft:grass
fill ~4 ~110 ~40 ~5 ~110 ~42 minecraft:grass
fill ~4 ~110 ~52 ~6 ~110 ~52 minecraft:stained_hardened_clay ["color"="red"]
fill ~4 ~110 ~53 ~102 ~110 ~60 minecraft:stone ["stone_type"="stone"]
fill ~4 ~111 ~39 ~4 ~111 ~40 minecraft:fence ["wood_type"="oak"]
fill ~4 ~111 ~52 ~6 ~111 ~52 minecraft:carpet ["color"="red"]
fill ~4 ~111 ~53 ~5 ~111 ~53 minecraft:furnace ["facing_direction"=2]
fill ~4 ~112 ~48 ~4 ~113 ~48 minecraft:stained_hardened_clay ["color"="red"]
fill ~4 ~112 ~53 ~4 ~113 ~53 minecraft:stained_hardened_clay ["color"="red"]
fill ~4 ~113 ~54 ~7 ~113 ~54 minecraft:dirt ["dirt_type"="normal"]
fill ~4 ~113 ~62 ~101 ~114 ~65 minecraft:stone ["stone_type"="stone"]
fill ~4 ~113 ~68 ~4 ~115 ~68 minecraft:sand ["sand_type"="normal"]
fill ~4 ~114 ~54 ~7 ~115 ~54 minecraft:stained_hardened_clay ["color"="orange"]
fill ~4 ~114 ~61 ~101 ~114 ~65 minecraft:stone ["stone_type"="stone"]
fill ~4 ~114 ~67 ~4 ~115 ~68 minecraft:sand ["sand_type"="normal"]
fill ~4 ~115 ~59 ~5 ~115 ~59 minecraft:grass
fill ~4 ~115 ~66 ~5 ~115 ~66 minecraft:sand ["sand_type"="normal"]
fill ~4 ~116 ~49 ~7 ~116 ~53 minecraft:stained_hardened_clay ["color"="orange"]
fill ~4 ~116 ~54 ~8 ~116 ~54 minecraft:stone_block_slab4 ["top_slot_bit"=false,"stone_slab_type_4"="stone"]
fill ~4 ~116 ~57 ~4 ~116 ~58 minecraft:tallgrass ["tall_grass_type"="tall"]
fill ~4 ~116 ~61 ~4 ~116 ~65 minecraft:tallgrass ["tall_grass_type"="tall"]
fill ~4 ~117 ~49 ~7 ~117 ~49 minecraft:stone_block_slab4 ["top_slot_bit"=false,"stone_slab_type_4"="stone"]
fill ~4 ~117 ~50 ~4 ~117 ~53 minecraft:stone_block_slab4 ["top_slot_bit"=false,"stone_slab_type_4"="stone"]
fill ~4 ~118 ~59 ~4 ~121 ~59 minecraft:leaves ["persistent_bit"=true,"update_bit"=false,"old_leaf_type"="oak"]
fill ~4 ~122 ~38 ~100 ~132 ~40 minecraft:stone ["stone_type"="stone"]
fill ~4 ~122 ~46 ~4 ~144 ~46 minecraft:stone ["stone_type"="stone"]
fill ~4 ~123 ~49 ~102 ~129 ~49 minecraft:stone ["stone_type"="stone"]
fill ~4 ~125 ~66 ~100 ~129 ~67 minecraft:stone ["stone_type"="stone"]
fill ~4 ~126 ~68 ~100 ~129 ~68 minecraft:stone ["stone_type"="stone"]
fill ~4 ~130 ~66 ~99 ~130 ~68 minecraft:stone ["stone_type"="stone"]
fill ~4 ~131 ~66 ~90 ~144 ~68 minecraft:stone ["stone_type"="stone"]
fill ~4 ~133 ~38 ~99 ~134 ~39 minecraft:stone ["stone_type"="stone"]
fill ~4 ~133 ~40 ~97 ~134 ~40 minecraft:stone ["stone_type"="stone"]
fill ~4 ~135 ~38 ~92 ~143 ~38 minecraft:stone ["stone_type"="stone"]
fill ~4 ~135 ~39 ~92 ~142 ~39 minecraft:stone ["stone_type"="stone"]
fill ~4 ~135 ~40 ~92 ~141 ~68 minecraft:stone ["stone_type"="stone"]
fill ~4 ~142 ~40 ~4 ~144 ~40 minecraft:log ["pillar_axis"="y","old_log_type"="spruce"]
fill ~4 ~143 ~39 ~4 ~144 ~40 minecraft:log ["pillar_axis"="y","old_log_type"="spruce"]
fill ~4 ~143 ~41 ~95 ~144 ~59 minecraft:stone ["stone_type"="stone"]
fill ~4 ~144 ~38 ~4 ~144 ~40 minecraft:log ["pillar_axis"="y","old_log_type"="spruce"]
fill ~4 ~145 ~38 ~4 ~145 ~43 minecraft:wood ["stripped_bit"=false,"pillar_axis"="y","wood_type"="spruce"]
fill ~4 ~145 ~66 ~4 ~148 ~66 minecraft:dirt ["dirt_type"="normal"]
fill ~4 ~145 ~67 ~100 ~145 ~68 minecraft:stone ["stone_type"="stone"]
fill ~4 ~146 ~61 ~12 ~146 ~65 minecraft:stone ["stone_type"="stone"]
fill ~4 ~146 ~67 ~4 ~148 ~67 minecraft:dirt ["dirt_type"="normal"]
fill ~4 ~146 ~68 ~100 ~147 ~68 minecraft:stone ["stone_type"="stone"]
fill ~4 ~147 ~49 ~102 ~147 ~58 minecraft:stone ["stone_type"="stone"]
fill ~4 ~147 ~61 ~11 ~148 ~65 minecraft:stone ["stone_type"="stone"]
fill ~4 ~148 ~51 ~102 ~148 ~57 minecraft:stone ["stone_type"="stone"]
fill ~4 ~149 ~51 ~6 ~149 ~51 minecraft:grass
fill ~4 ~149 ~53 ~8 ~149 ~53 minecraft:packed_ice
fill ~4 ~149 ~56 ~5 ~149 ~57 minecraft:grass
fill ~4 ~149 ~61 ~4 ~149 ~68 minecraft:grass
fill ~4 ~150 ~51 ~6 ~150 ~51 minecraft:snow_layer ["covered_bit"=false,"height"=0]
fill ~4 ~150 ~56 ~5 ~150 ~57 minecraft:snow_layer ["covered_bit"=false,"height"=0]
fill ~4 ~150 ~61 ~4 ~150 ~62 minecraft:snow_layer ["covered_bit"=false,"height"=0]
fill ~4 ~152 ~56 ~4 ~154 ~56 minecraft:leaves ["persistent_bit"=true,"update_bit"=false,"old_leaf_type"="spruce"]
fill ~4 ~153 ~55 ~5 ~153 ~55 minecraft:snow_layer ["covered_bit"=false,"height"=0]
fill ~4 ~153 ~57 ~5 ~153 ~57 minecraft:snow_layer ["covered_bit"=false,"height"=0]
fill ~4 ~154 ~72 ~8 ~154 ~72 minecraft:leaves ["persistent_bit"=true,"update_bit"=false,"old_leaf_type"="spruce"]
fill ~4 ~154 ~73 ~5 ~154 ~74 minecraft:leaves ["persistent_bit"=true,"update_bit"=false,"old_leaf_type"="spruce"]
fill ~4 ~155 ~55 ~5 ~155 ~56 minecraft:snow_layer ["covered_bit"=false,"height"=0]
fill ~4 ~155 ~72 ~5 ~155 ~72 minecraft:snow_layer ["covered_bit"=false,"height"=0]
fill ~4 ~157 ~38 ~100 ~166 ~38 minecraft:stone ["stone_type"="stone"]
fill ~4 ~157 ~39 ~100 ~165 ~39 minecraft:stone ["stone_type"="stone"]
fill ~4 ~157 ~40 ~100 ~163 ~48 minecraft:stone ["stone_type"="stone"]
fill ~4 ~160 ~66 ~100 ~162 ~68 minecraft:stone ["stone_type"="stone"]
fill ~4 ~163 ~66 ~99 ~164 ~68 minecraft:stone ["stone_type"="stone"]
fill ~4 ~164 ~40 ~99 ~164 ~40 minecraft:stone ["stone_type"="stone"]
fill ~4 ~165 ~40 ~96 ~166 ~40 minecraft:stone ["stone_type"="stone"]
fill ~4 ~165 ~66 ~87 ~166 ~66 minecraft:stone ["stone_type"="stone"]
fill ~4 ~165 ~67 ~87 ~165 ~68 minecraft:stone ["stone_type"="stone"]
fill ~4 ~166 ~39 ~96 ~166 ~40 minecraft:stone ["stone_type"="stone"]
fill ~4 ~166 ~67 ~86 ~167 ~68 minecraft:stone ["stone_type"="stone"]
fill ~4 ~167 ~38 ~94 ~167 ~39 minecraft:stone ["stone_type"="stone"]
fill ~4 ~167 ~40 ~93 ~167 ~40 minecraft:stone ["stone_type"="stone"]
fill ~4 ~167 ~66 ~86 ~167 ~68 minecraft:stone ["stone_type"="stone"]
fill ~4 ~168 ~38 ~87 ~174 ~38 minecraft:stone ["stone_type"="stone"]
fill ~4 ~168 ~39 ~87 ~173 ~39 minecraft:stone ["stone_type"="stone"]
fill ~4 ~168 ~40 ~91 ~172 ~49 minecraft:stone ["stone_type"="stone"]
fill ~4 ~168 ~66 ~48 ~175 ~66 minecraft:stone ["stone_type"="stone"]
fill ~4 ~168 ~67 ~48 ~174 ~67 minecraft:stone ["stone_type"="stone"]
fill ~4 ~168 ~68 ~48 ~173 ~68 minecraft:stone ["stone_type"="stone"]
fill ~4 ~173 ~40 ~4 ~176 ~40 minecraft:dirt ["dirt_type"="normal"]
fill ~4 ~174 ~39 ~4 ~176 ~40 minecraft:dirt ["dirt_type"="normal"]
fill ~4 ~174 ~41 ~92 ~176 ~45 minecraft:stone ["stone_type"="stone"]
fill ~4 ~174 ~63 ~51 ~174 ~67 minecraft:stone ["stone_type"="stone"]
fill ~4 ~174 ~68 ~4 ~176 ~68 minecraft:dirt ["dirt_type"="normal"]
fill ~4 ~175 ~38 ~4 ~176 ~40 minecraft:dirt ["dirt_type"="normal"]
fill ~4 ~175 ~61 ~49 ~176 ~61 minecraft:stone ["stone_type"="stone"]
fill ~4 ~175 ~62 ~47 ~176 ~65 minecraft:stone ["stone_type"="stone"]
fill ~4 ~175 ~67 ~4 ~176 ~68 minecraft:dirt ["dirt_type"="normal"]
fill ~4 ~176 ~66 ~4 ~176 ~68 minecraft:dirt ["dirt_type"="normal"]
fill ~4 ~177 ~38 ~11 ~177 ~45 minecraft:grass
fill ~4 ~177 ~50 ~9 ~177 ~50 minecraft:grass
fill ~4 ~177 ~66 ~7 ~177 ~68 minecraft:grass
fill ~4 ~178 ~47 ~4 ~178 ~48 minecraft:leaves ["persistent_bit"=false,"update_bit"=false,"old_leaf_type"="jungle"]
fill ~4 ~178 ~55 ~6 ~178 ~55 minecraft:leaves ["persistent_bit"=false,"update_bit"=false,"old_leaf_type"="jungle"]
fill ~4 ~178 ~56 ~4 ~188 ~56 minecraft:vine ["vine_direction_bits"=8]
fill ~4 ~178 ~61 ~7 ~178 ~61 minecraft:leaves ["persistent_bit"=true,"update_bit"=false,"old_leaf_type"="jungle"]
fill ~4 ~178 ~65 ~5 ~178 ~65 minecraft:tallgrass ["tall_grass_type"="tall"]
fill ~4 ~178 ~67 ~4 ~178 ~68 minecraft:tallgrass ["tall_grass_type"="tall"]
fill ~4 ~179 ~57 ~4 ~180 ~57 minecraft:vine ["vine_direction_bits"=8]
fill ~4 ~183 ~57 ~4 ~185 ~57 minecraft:vine ["vine_direction_bits"=8]
fill ~4 ~185 ~58 ~6 ~185 ~58 minecraft:leaves ["persistent_bit"=true,"update_bit"=false,"old_leaf_type"="jungle"]
fill ~4 ~185 ~59 ~4 ~186 ~61 minecraft:leaves ["persistent_bit"=false,"update_bit"=false,"old_leaf_type"="jungle"]
fill ~4 ~185 ~62 ~7 ~185 ~62 minecraft:leaves ["persistent_bit"=false,"update_bit"=false,"old_leaf_type"="jungle"]
fill ~4 ~186 ~50 ~4 ~189 ~50 minecraft:leaves ["persistent_bit"=true,"update_bit"=false,"old_leaf_type"="jungle"]
fill ~4 ~187 ~60 ~6 ~187 ~60 minecraft:leaves ["persistent_bit"=false,"update_bit"=false,"old_leaf_type"="jungle"]
fill ~4 ~189 ~55 ~7 ~190 ~55 minecraft:leaves ["persistent_bit"=true,"update_bit"=false,"old_leaf_type"="jungle"]
fill ~4 ~189 ~56 ~4 ~191 ~57 minecraft:leaves ["persistent_bit"=true,"update_bit"=false,"old_leaf_type"="jungle"]
fill ~4 ~189 ~58 ~7 ~190 ~58 minecraft:leaves ["persistent_bit"=true,"update_bit"=false,"old_leaf_type"="jungle"]
fill ~4 ~189 ~59 ~10 ~189 ~60 minecraft:leaves ["persistent_bit"=false,"update_bit"=false,"old_leaf_type"="jungle"]
fill ~4 ~190 ~59 ~9 ~190 ~59 minecraft:leaves ["persistent_bit"=false,"update_bit"=false,"old_leaf_type"="jungle"]
fill ~4 ~191 ~55 ~6 ~191 ~57 minecraft:leaves ["persistent_bit"=true,"update_bit"=false,"old_leaf_type"="jungle"]
fill ~4 ~191 ~58 ~8 ~191 ~59 minecraft:leaves ["persistent_bit"=false,"update_bit"=false,"old_leaf_type"="jungle"]
fill ~5 ~0 ~35 ~92 ~9 ~71 minecraft:stone ["stone_type"="stone"]
fill ~93 ~0 ~35 ~99 ~9 ~71 minecraft:stone ["stone_type"="stone"]
fill ~5 ~10 ~35 ~6 ~10 ~35 minecraft:stone ["stone_type"="stone"]
fill ~5 ~10 ~36 ~5 ~10 ~39 minecraft:stone ["stone_type"="stone"]
fill ~5 ~10 ~69 ~99 ~12 ~71 minecraft:stone ["stone_type"="stone"]
fill ~5 ~11 ~40 ~100 ~11 ~68 minecraft:stone ["stone_type"="stone"]
fill ~5 ~12 ~42 ~14 ~12 ~42 minecraft:dirt ["dirt_type"="normal"]
fill ~5 ~12 ~43 ~6 ~12 ~44 minecraft:grass
fill ~5 ~12 ~45 ~7 ~12 ~45 minecraft:water ["liquid_depth"=0]
fill ~5 ~12 ~47 ~11 ~12 ~48 minecraft:grass
fill ~5 ~12 ~50 ~10 ~12 ~51 minecraft:grass
fill ~5 ~12 ~52 ~5 ~12 ~53 minecraft:water ["liquid_depth"=0]
fill ~5 ~12 ~57 ~6 ~12 ~62 minecraft:grass
fill ~5 ~12 ~66 ~14 ~12 ~66 minecraft:dirt ["dirt_type"="normal"]
fill ~5 ~13 ~40 ~5 ~13 ~42 minecraft:grass
fill ~5 ~13 ~62 ~6 ~13 ~62 minecraft:tallgrass ["tall_grass_type"="tall"]
fill ~5 ~13 ~66 ~6 ~15 ~66 minecraft:stone ["stone_type"="stone"]
fill ~5 ~13 ~69 ~5 ~15 ~69 minecraft:end_stone
fill ~5 ~13 ~70 ~99 ~13 ~71 minecraft:stone ["stone_type"="stone"]
fill ~5 ~14 ~47 ~5 ~15 ~50 minecraft:leaves ["persistent_bit"=true,"update_bit"=false,"old_leaf_type"="oak"]
fill ~5 ~14 ~51 ~7 ~15 ~51 minecraft:leaves ["persistent_bit"=false,"update_bit"=false,"old_leaf_type"="oak"]
fill ~5 ~14 ~57 ~5 ~17 ~57 minecraft:leaves ["persistent_bit"=true,"update_bit"=false,"old_leaf_type"="oak"]
fill ~5 ~14 ~70 ~5 ~15 ~71 minecraft:end_stone
fill ~5 ~15 ~68 ~10 ~15 ~69 minecraft:end_stone
fill ~5 ~16 ~41 ~5 ~19 ~41 minecraft:leaves ["persistent_bit"=true,"update_bit"=false,"old_leaf_type"="oak"]
fill ~5 ~16 ~49 ~5 ~17 ~49 minecraft:leaves ["persistent_bit"=true,"update_bit"=false,"old_leaf_type"="oak"]
fill ~5 ~21 ~35 ~99 ~21 ~35 minecraft:stone ["stone_type"="stone"]
fill ~5 ~21 ~36 ~12 ~21 ~36 minecraft:stone ["stone_type"="stone"]
fill ~5 ~22 ~35 ~8 ~36 ~35 minecraft:stone ["stone_type"="stone"]
fill ~5 ~22 ~36 ~6 ~35 ~36 minecraft:stone ["stone_type"="stone"]
fill ~5 ~22 ~37 ~5 ~35 ~38 minecraft:stone ["stone_type"="stone"]
fill ~5 ~22 ~52 ~102 ~26 ~52 minecraft:stone ["stone_type"="stone"]
fill ~5 ~23 ~39 ~5 ~38 ~61 minecraft:stone ["stone_type"="stone"]
fill ~5 ~24 ~69 ~99 ~24 ~69 minecraft:stone ["stone_type"="stone"]
fill ~5 ~24 ~70 ~5 ~40 ~70 minecraft:stone ["stone_type"="stone"]
fill ~5 ~25 ~69 ~91 ~28 ~69 minecraft:stone ["stone_type"="stone"]
fill ~5 ~25 ~71 ~89 ~39 ~71 minecraft:stone ["stone_type"="stone"]
fill ~5 ~29 ~69 ~90 ~29 ~69 minecraft:stone ["stone_type"="stone"]
fill ~5 ~30 ~69 ~89 ~39 ~71 minecraft:stone ["stone_type"="stone"]
fill ~5 ~36 ~36 ~5 ~40 ~37 minecraft:netherrack
fill ~5 ~37 ~35 ~5 ~39 ~37 minecraft:netherrack
fill ~5 ~37 ~38 ~100 ~38 ~39 minecraft:stone ["stone_type"="stone"]
fill ~5 ~39 ~38 ~7 ~39 ~38 minecraft:netherrack
fill ~5 ~39 ~39 ~6 ~39 ~39 minecraft:magma
fill ~5 ~39 ~42 ~8 ~39 ~43 minecraft:lava ["liquid_depth"=0]
fill ~5 ~39 ~46 ~5 ~40 ~46 minecraft:magma
fill ~5 ~39 ~48 ~6 ~39 ~48 minecraft:netherrack
fill ~5 ~39 ~49 ~6 ~39 ~52 minecraft:lava ["liquid_depth"=0]
fill ~5 ~39 ~66 ~100 ~41 ~68 minecraft:stone ["stone_type"="stone"]
fill ~5 ~40 ~45 ~6 ~41 ~45 minecraft:netherrack
fill ~5 ~40 ~69 ~5 ~41 ~69 minecraft:dirt ["dirt_type"="normal"]
fill ~5 ~40 ~71 ~5 ~42 ~71 minecraft:dirt ["dirt_type"="normal"]
fill ~5 ~41 ~35 ~7 ~41 ~35 minecraft:netherrack
fill ~5 ~41 ~70 ~5 ~41 ~71 minecraft:dirt ["dirt_type"="normal"]
fill ~5 ~42 ~35 ~6 ~42 ~36 minecraft:netherrack
fill ~5 ~42 ~58 ~102 ~42 ~58 minecraft:stone ["stone_type"="stone"]
fill ~5 ~42 ~59 ~5 ~42 ~60 minecraft:planks ["wood_type"="oak"]
fill ~5 ~42 ~68 ~5 ~42 ~70 minecraft:grass
fill ~5 ~43 ~58 ~5 ~45 ~58 minecraft:planks ["wood_type"="oak"]
fill ~5 ~43 ~67 ~5 ~49 ~67 minecraft:wood ["stripped_bit"=false,"pillar_axis"="y","wood_type"="oak"]
fill ~5 ~43 ~71 ~5 ~49 ~71 minecraft:wood ["stripped_bit"=false,"pillar_axis"="y","wood_type"="oak"]
fill ~5 ~45 ~68 ~5 ~45 ~71 minecraft:wood ["stripped_bit"=false,"pillar_axis"="y","wood_type"="oak"]
fill ~5 ~49 ~68 ~5 ~49 ~71 minecraft:wood ["stripped_bit"=false,"pillar_axis"="y","wood_type"="oak"]
fill ~5 ~50 ~35 ~99 ~60 ~35 minecraft:stone ["stone_type"="stone"]
fill ~5 ~50 ~36 ~99 ~59 ~41 minecraft:stone ["stone_type"="stone"]
fill ~5 ~51 ~51 ~102 ~57 ~51 minecraft:stone ["stone_type"="stone"]
fill ~5 ~52 ~59 ~102 ~57 ~59 minecraft:stone ["stone_type"="stone"]
fill ~5 ~53 ~62 ~101 ~57 ~63 minecraft:stone ["stone_type"="stone"]
fill ~5 ~54 ~69 ~99 ~55 ~69 minecraft:stone ["stone_type"="stone"]
fill ~5 ~54 ~70 ~8 ~77 ~70 minecraft:stone ["stone_type"="stone"]
fill ~5 ~54 ~71 ~7 ~76 ~71 minecraft:stone ["stone_type"="stone"]
fill ~5 ~56 ~69 ~74 ~63 ~71 minecraft:stone ["stone_type"="stone"]
fill ~5 ~60 ~36 ~98 ~61 ~37 minecraft:stone ["stone_type"="stone"]
fill ~5 ~61 ~35 ~98 ~61 ~37 minecraft:stone ["stone_type"="stone"]
fill ~5 ~62 ~35 ~96 ~63 ~35 minecraft:stone ["stone_type"="stone"]
fill ~5 ~62 ~36 ~95 ~62 ~36 minecraft:stone ["stone_type"="stone"]
fill ~5 ~62 ~37 ~94 ~63 ~37 minecraft:stone ["stone_type"="stone"]
fill ~5 ~63 ~36 ~91 ~63 ~59 minecraft:stone ["stone_type"="stone"]
fill ~5 ~64 ~35 ~81 ~74 ~37 minecraft:stone ["stone_type"="stone"]
fill ~5 ~64 ~69 ~29 ~77 ~70 minecraft:stone ["stone_type"="stone"]
fill ~5 ~75 ~35 ~7 ~75 ~35 minecraft:stone ["stone_type"="stone"]
fill ~5 ~75 ~36 ~6 ~75 ~43 minecraft:stone ["stone_type"="stone"]
fill ~5 ~75 ~44 ~6 ~75 ~46 minecraft:flowing_water ["liquid_depth"=8]
fill ~5 ~76 ~35 ~6 ~76 ~35 minecraft:stone ["stone_type"="stone"]
fill ~5 ~76 ~36 ~5 ~76 ~43 minecraft:stone ["stone_type"="stone"]
fill ~5 ~76 ~44 ~6 ~76 ~48 minecraft:water ["liquid_depth"=0]
fill ~5 ~76 ~50 ~5 ~76 ~54 minecraft:flowing_water ["liquid_depth"=8]
fill ~5 ~76 ~55 ~7 ~76 ~71 minecraft:stone ["stone_type"="stone"]
fill ~5 ~77 ~40 ~5 ~77 ~42 minecraft:gold_block
fill ~5 ~77 ~58 ~102 ~77 ~60 minecraft:stone ["stone_type"="stone"]
fill ~5 ~77 ~66 ~100 ~78 ~68 minecraft:stone ["stone_type"="stone"]
fill ~5 ~77 ~71 ~5 ~79 ~71 minecraft:magma
fill ~5 ~78 ~49 ~5 ~86 ~49 minecraft:flowing_water ["liquid_depth"=8]
fill ~5 ~78 ~54 ~5 ~86 ~54 minecraft:flowing_water ["liquid_depth"=8]
fill ~5 ~78 ~59 ~9 ~78 ~68 minecraft:stone ["stone_type"="stone"]
fill ~5 ~78 ~69 ~5 ~79 ~71 minecraft:magma
fill ~5 ~79 ~59 ~7 ~79 ~59 minecraft:magma
fill ~5 ~79 ~60 ~9 ~79 ~62 minecraft:lava ["liquid_depth"=0]
fill ~5 ~79 ~66 ~12 ~79 ~67 minecraft:lava ["liquid_depth"=0]
fill ~5 ~79 ~68 ~8 ~79 ~68 minecraft:lava ["liquid_depth"=0]
fill ~5 ~85 ~68 ~6 ~114 ~68 minecraft:stone ["stone_type"="stone"]
fill ~5 ~86 ~35 ~99 ~88 ~35 minecraft:stone ["stone_type"="stone"]
fill ~5 ~86 ~36 ~5 ~107 ~37 minecraft:stone ["stone_type"="stone"]
fill ~5 ~86 ~38 ~8 ~86 ~38 minecraft:stone ["stone_type"="andesite"]
fill ~5 ~86 ~39 ~6 ~86 ~39 minecraft:stone ["stone_type"="andesite"]
fill ~5 ~87 ~38 ~100 ~87 ~48 minecraft:stone ["stone_type"="stone"]
fill ~5 ~87 ~50 ~101 ~91 ~53 minecraft:stone ["stone_type"="stone"]
fill ~5 ~87 ~55 ~102 ~87 ~55 minecraft:stone ["stone_type"="stone"]
fill ~5 ~87 ~66 ~5 ~114 ~68 minecraft:stone ["stone_type"="stone"]
fill ~5 ~87 ~69 ~6 ~112 ~69 minecraft:stone ["stone_type"="stone"]
fill ~5 ~88 ~38 ~99 ~91 ~53 minecraft:stone ["stone_type"="stone"]
fill ~5 ~88 ~54 ~101 ~90 ~56 minecraft:stone ["stone_type"="stone"]
fill ~5 ~88 ~59 ~102 ~88 ~59 minecraft:stone ["stone_type"="stone"]
fill ~5 ~89 ~35 ~98 ~93 ~35 minecraft:stone ["stone_type"="stone"]
fill ~5 ~89 ~70 ~98 ~89 ~71 minecraft:stone ["stone_type"="stone"]
fill ~5 ~90 ~70 ~88 ~113 ~71 minecraft:stone ["stone_type"="stone"]
fill ~5 ~91 ~54 ~93 ~91 ~59 minecraft:stone ["stone_type"="stone"]
fill ~5 ~92 ~38 ~92 ~97 ~49 minecraft:stone ["stone_type"="stone"]
fill ~5 ~92 ~50 ~92 ~96 ~61 minecraft:stone ["stone_type"="stone"]
fill ~5 ~94 ~35 ~82 ~106 ~36 minecraft:stone ["stone_type"="stone"]
fill ~5 ~97 ~50 ~91 ~109 ~66 minecraft:stone ["stone_type"="stone"]
fill ~5 ~98 ~38 ~91 ~104 ~67 minecraft:stone ["stone_type"="stone"]
fill ~5 ~105 ~38 ~12 ~105 ~71 minecraft:stone ["stone_type"="stone"]
fill ~5 ~106 ~38 ~11 ~107 ~71 minecraft:stone ["stone_type"="stone"]
fill ~5 ~107 ~35 ~5 ~109 ~35 minecraft:dirt ["dirt_type"="normal"]
fill ~5 ~108 ~36 ~5 ~109 ~36 minecraft:dirt ["dirt_type"="normal"]
fill ~5 ~108 ~37 ~11 ~108 ~37 minecraft:stone ["stone_type"="stone"]
fill ~5 ~108 ~38 ~10 ~109 ~71 minecraft:stone ["stone_type"="stone"]
fill ~5 ~110 ~35 ~8 ~110 ~35 minecraft:grass
fill ~5 ~110 ~36 ~7 ~110 ~38 minecraft:grass
fill ~5 ~110 ~44 ~5 ~110 ~45 minecraft:grass
fill ~5 ~110 ~46 ~5 ~110 ~47 minecraft:gravel
fill ~5 ~110 ~48 ~5 ~110 ~52 minecraft:stained_hardened_clay ["color"="red"]
fill ~5 ~113 ~53 ~6 ~113 ~53 minecraft:stained_hardened_clay ["color"="red"]
fill ~5 ~113 ~69 ~5 ~115 ~69 minecraft:sand ["sand_type"="normal"]
fill ~5 ~114 ~29 ~9 ~115 ~29 minecraft:leaves ["persistent_bit"=true,"update_bit"=false,"old_leaf_type"="oak"]
fill ~5 ~114 ~30 ~8 ~117 ~30 minecraft:leaves ["persistent_bit"=true,"update_bit"=false,"old_leaf_type"="oak"]
fill ~5 ~114 ~31 ~5 ~115 ~31 minecraft:leaves ["persistent_bit"=true,"update_bit"=false,"old_leaf_type"="oak"]
fill ~5 ~114 ~70 ~5 ~115 ~70 minecraft:sand ["sand_type"="normal"]
fill ~5 ~114 ~71 ~99 ~114 ~71 minecraft:stone ["stone_type"="stone"]
fill ~5 ~115 ~49 ~6 ~115 ~49 minecraft:glass_pane
fill ~5 ~115 ~60 ~6 ~115 ~60 minecraft:dirt ["dirt_type"="normal"]
fill ~5 ~115 ~62 ~5 ~115 ~65 minecraft:grass
fill ~5 ~115 ~67 ~8 ~115 ~68 minecraft:dirt ["dirt_type"="normal"]
fill ~5 ~115 ~71 ~6 ~115 ~71 minecraft:sand ["sand_type"="normal"]
fill ~5 ~116 ~60 ~6 ~116 ~60 minecraft:grass
fill ~5 ~116 ~63 ~8 ~116 ~63 minecraft:tallgrass ["tall_grass_type"="tall"]
fill ~5 ~116 ~67 ~5 ~116 ~68 minecraft:sandstone ["sand_stone_type"="default"]
fill ~5 ~117 ~31 ~9 ~117 ~31 minecraft:leaves ["persistent_bit"=true,"update_bit"=false,"old_leaf_type"="oak"]
fill ~5 ~117 ~53 ~7 ~117 ~53 minecraft:stone_block_slab4 ["top_slot_bit"=false,"stone_slab_type_4"="stone"]
fill ~5 ~117 ~60 ~6 ~117 ~60 minecraft:tallgrass ["tall_grass_type"="tall"]
fill ~5 ~117 ~67 ~8 ~117 ~68 minecraft:sand ["sand_type"="normal"]
fill ~5 ~118 ~58 ~5 ~119 ~60 minecraft:leaves ["persistent_bit"=false,"update_bit"=false,"old_leaf_type"="oak"]
fill ~5 ~118 ~68 ~5 ~120 ~68 minecraft:cactus ["age"=0]
fill ~5 ~121 ~35 ~99 ~132 ~36 minecraft:stone ["stone_type"="stone"]
fill ~5 ~122 ~37 ~99 ~131 ~40 minecraft:stone ["stone_type"="stone"]
fill ~5 ~126 ~69 ~99 ~128 ~70 minecraft:stone ["stone_type"="stone"]
fill ~5 ~126 ~71 ~99 ~127 ~71 minecraft:stone ["stone_type"="stone"]
fill ~5 ~128 ~71 ~90 ~146 ~71 minecraft:stone ["stone_type"="stone"]
fill ~5 ~129 ~69 ~98 ~130 ~69 minecraft:stone ["stone_type"="stone"]
fill ~5 ~129 ~70 ~91 ~129 ~70 minecraft:stone ["stone_type"="stone"]
fill ~5 ~130 ~70 ~90 ~145 ~71 minecraft:stone ["stone_type"="stone"]
fill ~5 ~131 ~69 ~90 ~147 ~69 minecraft:stone ["stone_type"="stone"]
fill ~5 ~132 ~37 ~98 ~134 ~39 minecraft:stone ["stone_type"="stone"]
fill ~5 ~133 ~35 ~98 ~134 ~39 minecraft:stone ["stone_type"="stone"]
fill ~5 ~135 ~35 ~89 ~142 ~71 minecraft:stone ["stone_type"="stone"]
fill ~5 ~143 ~35 ~5 ~144 ~35 minecraft:log ["pillar_axis"="y","old_log_type"="spruce"]
fill ~5 ~143 ~36 ~91 ~143 ~71 minecraft:stone ["stone_type"="stone"]
fill ~5 ~144 ~36 ~5 ~144 ~37 minecraft:log ["pillar_axis"="y","old_log_type"="spruce"]
fill ~5 ~144 ~38 ~15 ~144 ~59 minecraft:stone ["stone_type"="stone"]
fill ~5 ~145 ~35 ~14 ~145 ~37 minecraft:wood ["stripped_bit"=false,"pillar_axis"="y","wood_type"="spruce"]
fill ~5 ~145 ~38 ~6 ~145 ~39 minecraft:slime
fill ~5 ~145 ~40 ~7 ~145 ~46 minecraft:wood ["stripped_bit"=false,"pillar_axis"="y","wood_type"="spruce"]
fill ~5 ~145 ~66 ~100 ~146 ~68 minecraft:stone ["stone_type"="stone"]
fill ~5 ~146 ~35 ~5 ~146 ~37 minecraft:fence ["wood_type"="oak"]
fill ~5 ~146 ~47 ~5 ~146 ~69 minecraft:stone ["stone_type"="stone"]
fill ~5 ~146 ~70 ~5 ~148 ~70 minecraft:dirt ["dirt_type"="normal"]
fill ~5 ~147 ~47 ~7 ~147 ~47 minecraft:dirt ["dirt_type"="normal"]
fill ~5 ~147 ~48 ~102 ~147 ~58 minecraft:stone ["stone_type"="stone"]
fill ~5 ~147 ~66 ~12 ~148 ~68 minecraft:stone ["stone_type"="stone"]
fill ~5 ~147 ~71 ~5 ~148 ~71 minecraft:dirt ["dirt_type"="normal"]
fill ~5 ~148 ~47 ~5 ~148 ~49 minecraft:grass
fill ~5 ~148 ~50 ~102 ~148 ~57 minecraft:stone ["stone_type"="stone"]
fill ~5 ~148 ~69 ~5 ~148 ~71 minecraft:dirt ["dirt_type"="normal"]
fill ~5 ~149 ~47 ~5 ~149 ~48 minecraft:snow_layer ["covered_bit"=false,"height"=0]
fill ~5 ~149 ~50 ~7 ~149 ~50 minecraft:grass
fill ~5 ~149 ~52 ~11 ~149 ~52 minecraft:packed_ice
fill ~5 ~149 ~59 ~9 ~149 ~60 minecraft:grass
fill ~5 ~149 ~62 ~10 ~149 ~62 minecraft:grass
fill ~5 ~149 ~63 ~5 ~149 ~71 minecraft:grass
fill ~5 ~150 ~50 ~7 ~150 ~50 minecraft:snow_layer ["covered_bit"=false,"height"=0]
fill ~5 ~150 ~59 ~8 ~150 ~60 minecraft:snow_layer ["covered_bit"=false,"height"=0]
fill ~5 ~150 ~62 ~10 ~150 ~62 minecraft:snow_layer ["covered_bit"=false,"height"=0]
fill ~5 ~150 ~63 ~5 ~150 ~66 minecraft:snow_layer ["covered_bit"=false,"height"=0]
fill ~5 ~150 ~68 ~10 ~150 ~69 minecraft:snow_layer ["covered_bit"=false,"height"=0]
fill ~5 ~152 ~55 ~5 ~152 ~56 minecraft:leaves ["persistent_bit"=false,"update_bit"=false,"old_leaf_type"="spruce"]
fill ~5 ~153 ~56 ~5 ~153 ~57 minecraft:snow_layer ["covered_bit"=false,"height"=0]
fill ~5 ~154 ~71 ~7 ~154 ~72 minecraft:leaves ["persistent_bit"=true,"update_bit"=false,"old_leaf_type"="spruce"]
fill ~5 ~154 ~75 ~7 ~154 ~75 minecraft:leaves ["persistent_bit"=true,"update_bit"=false,"old_leaf_type"="spruce"]
fill ~5 ~157 ~35 ~99 ~166 ~36 minecraft:stone ["stone_type"="stone"]
fill ~5 ~157 ~37 ~99 ~165 ~39 minecraft:stone ["stone_type"="stone"]
fill ~5 ~157 ~49 ~102 ~163 ~49 minecraft:stone ["stone_type"="stone"]
fill ~5 ~158 ~52 ~102 ~162 ~52 minecraft:stone ["stone_type"="stone"]
fill ~5 ~160 ~63 ~101 ~163 ~64 minecraft:stone ["stone_type"="stone"]
fill ~5 ~160 ~69 ~99 ~163 ~69 minecraft:stone ["stone_type"="stone"]
fill ~5 ~160 ~70 ~99 ~162 ~70 minecraft:stone ["stone_type"="stone"]
fill ~5 ~160 ~71 ~99 ~161 ~71 minecraft:stone ["stone_type"="stone"]
fill ~5 ~162 ~71 ~98 ~163 ~71 minecraft:stone ["stone_type"="stone"]
fill ~5 ~163 ~70 ~98 ~163 ~71 minecraft:stone ["stone_type"="stone"]
fill ~5 ~164 ~69 ~98 ~164 ~69 minecraft:stone ["stone_type"="stone"]
fill ~5 ~164 ~70 ~91 ~164 ~71 minecraft:stone ["stone_type"="stone"]
fill ~5 ~165 ~69 ~90 ~165 ~69 minecraft:stone ["stone_type"="stone"]
fill ~5 ~165 ~70 ~89 ~167 ~71 minecraft:stone ["stone_type"="stone"]
fill ~5 ~166 ~37 ~98 ~167 ~37 minecraft:stone ["stone_type"="stone"]
fill ~5 ~166 ~69 ~89 ~167 ~71 minecraft:stone ["stone_type"="stone"]
fill ~5 ~167 ~35 ~98 ~167 ~37 minecraft:stone ["stone_type"="stone"]
fill ~5 ~168 ~35 ~87 ~175 ~45 minecraft:stone ["stone_type"="stone"]
fill ~5 ~168 ~63 ~48 ~174 ~71 minecraft:stone ["stone_type"="stone"]
fill ~5 ~175 ~67 ~94 ~176 ~67 minecraft:stone ["stone_type"="stone"]
fill ~5 ~175 ~68 ~93 ~176 ~68 minecraft:stone ["stone_type"="stone"]
fill ~5 ~175 ~69 ~5 ~176 ~69 minecraft:dirt ["dirt_type"="normal"]
fill ~5 ~175 ~70 ~93 ~175 ~71 minecraft:stone ["stone_type"="stone"]
fill ~5 ~176 ~35 ~5 ~176 ~37 minecraft:dirt ["dirt_type"="normal"]
fill ~5 ~176 ~38 ~92 ~176 ~47 minecraft:stone ["stone_type"="stone"]
fill ~5 ~176 ~66 ~51 ~176 ~68 minecraft:stone ["stone_type"="stone"]
fill ~5 ~176 ~70 ~5 ~176 ~71 minecraft:dirt ["dirt_type"="normal"]
fill ~5 ~177 ~35 ~6 ~177 ~55 minecraft:grass
fill ~5 ~177 ~56 ~6 ~177 ~57 minecraft:dirt ["dirt_type"="normal"]
fill ~5 ~177 ~58 ~9 ~177 ~61 minecraft:grass
fill ~5 ~177 ~62 ~5 ~177 ~71 minecraft:grass
fill ~5 ~178 ~49 ~8 ~178 ~49 minecraft:leaves ["persistent_bit"=false,"update_bit"=false,"old_leaf_type"="jungle"]
fill ~5 ~178 ~51 ~6 ~178 ~51 minecraft:leaves ["persistent_bit"=false,"update_bit"=false,"old_leaf_type"="jungle"]
fill ~5 ~178 ~54 ~7 ~178 ~54 minecraft:leaves ["persistent_bit"=false,"update_bit"=false,"old_leaf_type"="jungle"]
fill ~5 ~178 ~56 ~6 ~189 ~57 minecraft:log ["pillar_axis"="y","old_log_type"="jungle"]
fill ~5 ~178 ~58 ~6 ~181 ~58 minecraft:vine ["vine_direction_bits"=4]
fill ~5 ~178 ~60 ~6 ~178 ~60 minecraft:leaves ["persistent_bit"=false,"update_bit"=false,"old_leaf_type"="jungle"]
fill ~5 ~178 ~63 ~6 ~178 ~64 minecraft:leaves ["persistent_bit"=true,"update_bit"=false,"old_leaf_type"="jungle"]
fill ~5 ~179 ~55 ~5 ~188 ~55 minecraft:vine ["vine_direction_bits"=1]
fill ~5 ~181 ~33 ~9 ~181 ~33 minecraft:leaves ["persistent_bit"=false,"update_bit"=false,"old_leaf_type"="jungle"]
fill ~5 ~181 ~34 ~5 ~182 ~36 minecraft:leaves ["persistent_bit"=false,"update_bit"=false,"old_leaf_type"="jungle"]
fill ~5 ~185 ~61 ~7 ~185 ~62 minecraft:leaves ["persistent_bit"=false,"update_bit"=false,"old_leaf_type"="jungle"]
fill ~5 ~185 ~71 ~5 ~186 ~73 minecraft:leaves ["persistent_bit"=false,"update_bit"=false,"old_leaf_type"="jungle"]
fill ~5 ~185 ~74 ~10 ~185 ~74 minecraft:leaves ["persistent_bit"=false,"update_bit"=false,"old_leaf_type"="jungle"]
fill ~5 ~185 ~76 ~8 ~185 ~76 minecraft:leaves ["persistent_bit"=false,"update_bit"=false,"old_leaf_type"="jungle"]
fill ~5 ~186 ~49 ~5 ~187 ~51 minecraft:leaves ["persistent_bit"=false,"update_bit"=false,"old_leaf_type"="jungle"]
fill ~5 ~186 ~59 ~6 ~186 ~59 minecraft:leaves ["persistent_bit"=false,"update_bit"=false,"old_leaf_type"="jungle"]
fill ~5 ~186 ~61 ~6 ~186 ~61 minecraft:leaves ["persistent_bit"=false,"update_bit"=false,"old_leaf_type"="jungle"]
fill ~5 ~186 ~70 ~8 ~186 ~70 minecraft:leaves ["persistent_bit"=false,"update_bit"=false,"old_leaf_type"="jungle"]
fill ~5 ~187 ~58 ~6 ~187 ~58 minecraft:vine ["vine_direction_bits"=4]
fill ~5 ~187 ~59 ~5 ~187 ~61 minecraft:leaves ["persistent_bit"=false,"update_bit"=false,"old_leaf_type"="jungle"]
fill ~5 ~188 ~76 ~8 ~188 ~77 minecraft:leaves ["persistent_bit"=false,"update_bit"=false,"old_leaf_type"="jungle"]
fill ~5 ~189 ~51 ~6 ~189 ~54 minecraft:leaves ["persistent_bit"=false,"update_bit"=false,"old_leaf_type"="jungle"]
fill ~5 ~189 ~62 ~6 ~189 ~62 minecraft:leaves ["persistent_bit"=false,"update_bit"=false,"old_leaf_type"="jungle"]
fill ~5 ~190 ~52 ~6 ~190 ~54 minecraft:leaves ["persistent_bit"=false,"update_bit"=false,"old_leaf_type"="jungle"]
fill ~5 ~190 ~57 ~7 ~190 ~58 minecraft:leaves ["persistent_bit"=true,"update_bit"=false,"old_leaf_type"="jungle"]
fill ~5 ~190 ~61 ~6 ~190 ~61 minecraft:leaves ["persistent_bit"=false,"update_bit"=false,"old_leaf_type"="jungle"]
fill ~5 ~191 ~53 ~6 ~191 ~54 minecraft:leaves ["persistent_bit"=false,"update_bit"=false,"old_leaf_type"="jungle"]
fill ~5 ~191 ~60 ~6 ~191 ~60 minecraft:leaves ["persistent_bit"=false,"update_bit"=false,"old_leaf_type"="jungle"]
fill ~6 ~0 ~33 ~84 ~9 ~73 minecraft:stone ["stone_type"="stone"]
fill ~85 ~0 ~33 ~98 ~9 ~73 minecraft:stone ["stone_type"="stone"]
fill ~6 ~10 ~33 ~6 ~10 ~35 minecraft:stone ["stone_type"="stone"]
fill ~6 ~10 ~36 ~8 ~10 ~36 minecraft:lava ["liquid_depth"=0]
fill ~6 ~10 ~37 ~6 ~10 ~73 minecraft:stone ["stone_type"="stone"]
fill ~6 ~11 ~72 ~98 ~12 ~73 minecraft:stone ["stone_type"="stone"]
fill ~6 ~12 ~41 ~10 ~12 ~41 minecraft:stone ["stone_type"="stone"]
fill ~6 ~12 ~52 ~9 ~12 ~52 minecraft:grass
fill ~6 ~12 ~53 ~6 ~12 ~55 minecraft:water ["liquid_depth"=0]
fill ~6 ~12 ~56 ~6 ~12 ~62 minecraft:grass
fill ~6 ~12 ~63 ~14 ~12 ~66 minecraft:dirt ["dirt_type"="normal"]
fill ~6 ~13 ~41 ~14 ~13 ~41 minecraft:grass
fill ~6 ~13 ~42 ~13 ~13 ~42 minecraft:grass
fill ~6 ~13 ~49 ~6 ~16 ~49 minecraft:log ["pillar_axis"="y","old_log_type"="oak"]
fill ~6 ~13 ~63 ~6 ~15 ~66 minecraft:stone ["stone_type"="stone"]
fill ~6 ~13 ~69 ~99 ~14 ~71 minecraft:stone ["stone_type"="stone"]
fill ~6 ~13 ~72 ~6 ~15 ~72 minecraft:end_stone
fill ~6 ~13 ~73 ~98 ~13 ~73 minecraft:stone ["stone_type"="stone"]
fill ~6 ~14 ~47 ~7 ~15 ~47 minecraft:leaves ["persistent_bit"=false,"update_bit"=false,"old_leaf_type"="oak"]
fill ~6 ~14 ~50 ~7 ~15 ~50 minecraft:leaves ["persistent_bit"=true,"update_bit"=false,"old_leaf_type"="oak"]
fill ~6 ~14 ~56 ~6 ~15 ~58 minecraft:leaves ["persistent_bit"=false,"update_bit"=false,"old_leaf_type"="oak"]
fill ~6 ~14 ~73 ~6 ~15 ~73 minecraft:end_stone
fill ~6 ~15 ~67 ~7 ~15 ~69 minecraft:end_stone
fill ~6 ~15 ~71 ~12 ~15 ~71 minecraft:end_stone
fill ~6 ~16 ~40 ~6 ~17 ~42 minecraft:leaves ["persistent_bit"=false,"update_bit"=false,"old_leaf_type"="oak"]
fill ~6 ~16 ~48 ~7 ~16 ~48 minecraft:leaves ["persistent_bit"=true,"update_bit"=false,"old_leaf_type"="oak"]
fill ~6 ~16 ~50 ~6 ~17 ~50 minecraft:leaves ["persistent_bit"=true,"update_bit"=false,"old_leaf_type"="oak"]
fill ~6 ~17 ~48 ~6 ~17 ~50 minecraft:leaves ["persistent_bit"=true,"update_bit"=false,"old_leaf_type"="oak"]
fill ~6 ~18 ~75 ~7 ~18 ~75 minecraft:chorus_plant
fill ~6 ~20 ~33 ~8 ~37 ~33 minecraft:stone ["stone_type"="stone"]
fill ~6 ~20 ~34 ~6 ~37 ~34 minecraft:stone ["stone_type"="stone"]
fill ~6 ~20 ~70 ~7 ~20 ~70 minecraft:chorus_plant
fill ~6 ~22 ~51 ~102 ~24 ~57 minecraft:stone ["stone_type"="stone"]
fill ~6 ~22 ~58 ~102 ~23 ~58 minecraft:stone ["stone_type"="stone"]
fill ~6 ~23 ~40 ~100 ~23 ~59 minecraft:stone ["stone_type"="stone"]
fill ~6 ~23 ~61 ~101 ~23 ~61 minecraft:stone ["stone_type"="stone"]
fill ~6 ~23 ~62 ~84 ~41 ~64 minecraft:stone ["stone_type"="stone"]
fill ~6 ~24 ~37 ~99 ~24 ~57 minecraft:stone ["stone_type"="stone"]
fill ~6 ~25 ~37 ~98 ~26 ~37 minecraft:stone ["stone_type"="stone"]
fill ~6 ~25 ~38 ~98 ~25 ~55 minecraft:stone ["stone_type"="stone"]
fill ~6 ~25 ~70 ~90 ~28 ~70 minecraft:stone ["stone_type"="stone"]
fill ~6 ~25 ~72 ~89 ~38 ~72 minecraft:stone ["stone_type"="stone"]
fill ~6 ~25 ~73 ~89 ~25 ~73 minecraft:stone ["stone_type"="stone"]
fill ~6 ~26 ~38 ~94 ~26 ~38 minecraft:stone ["stone_type"="stone"]
fill ~6 ~26 ~39 ~92 ~26 ~58 minecraft:stone ["stone_type"="stone"]
fill ~6 ~26 ~73 ~88 ~40 ~73 minecraft:stone ["stone_type"="stone"]
fill ~6 ~27 ~37 ~90 ~38 ~68 minecraft:stone ["stone_type"="stone"]
fill ~6 ~29 ~70 ~89 ~41 ~71 minecraft:stone ["stone_type"="stone"]
fill ~6 ~36 ~36 ~93 ~38 ~38 minecraft:stone ["stone_type"="stone"]
fill ~6 ~37 ~35 ~99 ~38 ~39 minecraft:stone ["stone_type"="stone"]
fill ~6 ~38 ~33 ~6 ~39 ~34 minecraft:netherrack
fill ~6 ~39 ~35 ~16 ~39 ~35 minecraft:netherrack
fill ~6 ~39 ~36 ~9 ~39 ~36 minecraft:netherrack
fill ~6 ~39 ~37 ~8 ~39 ~37 minecraft:netherrack
fill ~6 ~39 ~40 ~8 ~39 ~43 minecraft:lava ["liquid_depth"=0]
fill ~6 ~39 ~46 ~8 ~39 ~46 minecraft:netherrack
fill ~6 ~39 ~53 ~8 ~39 ~53 minecraft:netherrack
fill ~6 ~39 ~54 ~102 ~41 ~60 minecraft:stone ["stone_type"="stone"]
fill ~6 ~39 ~72 ~6 ~41 ~72 minecraft:dirt ["dirt_type"="normal"]
fill ~6 ~40 ~34 ~7 ~41 ~36 minecraft:netherrack
fill ~6 ~40 ~37 ~6 ~45 ~37 minecraft:netherrack
fill ~6 ~40 ~46 ~6 ~41 ~46 minecraft:netherrack
fill ~6 ~40 ~69 ~99 ~41 ~71 minecraft:stone ["stone_type"="stone"]
fill ~6 ~42 ~54 ~8 ~42 ~55 minecraft:grass
fill ~6 ~42 ~59 ~102 ~42 ~59 minecraft:stone ["stone_type"="stone"]
fill ~6 ~42 ~64 ~7 ~42 ~65 minecraft:slime
fill ~6 ~42 ~67 ~8 ~42 ~67 minecraft:grass
fill ~6 ~42 ~68 ~8 ~42 ~68 minecraft:dirt ["dirt_type"="normal"]
fill ~6 ~42 ~69 ~6 ~42 ~70 minecraft:dirt ["dirt_type"="normal"]
fill ~6 ~42 ~71 ~8 ~42 ~73 minecraft:grass
fill ~6 ~43 ~58 ~6 ~46 ~58 minecraft:wood ["stripped_bit"=false,"pillar_axis"="y","wood_type"="oak"]
fill ~6 ~43 ~59 ~6 ~45 ~59 minecraft:planks ["wood_type"="oak"]
fill ~6 ~43 ~61 ~6 ~46 ~61 minecraft:wood ["stripped_bit"=false,"pillar_axis"="y","wood_type"="oak"]
fill ~6 ~43 ~68 ~8 ~45 ~68 minecraft:planks ["wood_type"="oak"]
fill ~6 ~43 ~69 ~6 ~46 ~70 minecraft:planks ["wood_type"="oak"]
fill ~6 ~45 ~67 ~9 ~45 ~67 minecraft:wood ["stripped_bit"=false,"pillar_axis"="y","wood_type"="oak"]
fill ~6 ~45 ~71 ~9 ~45 ~71 minecraft:wood ["stripped_bit"=false,"pillar_axis"="y","wood_type"="oak"]
fill ~6 ~46 ~59 ~6 ~46 ~61 minecraft:wood ["stripped_bit"=false,"pillar_axis"="y","wood_type"="oak"]
fill ~6 ~46 ~68 ~6 ~48 ~68 minecraft:planks ["wood_type"="oak"]
fill ~6 ~47 ~70 ~6 ~48 ~70 minecraft:planks ["wood_type"="oak"]
fill ~6 ~48 ~69 ~8 ~48 ~70 minecraft:planks ["wood_type"="oak"]
fill ~6 ~49 ~67 ~9 ~49 ~67 minecraft:wood ["stripped_bit"=false,"pillar_axis"="y","wood_type"="oak"]
fill ~6 ~49 ~71 ~9 ~49 ~71 minecraft:wood ["stripped_bit"=false,"pillar_axis"="y","wood_type"="oak"]
fill ~6 ~50 ~33 ~98 ~62 ~33 minecraft:stone ["stone_type"="stone"]
fill ~6 ~50 ~34 ~98 ~60 ~42 minecraft:stone ["stone_type"="stone"]
fill ~6 ~51 ~52 ~102 ~57 ~52 minecraft:stone ["stone_type"="stone"]
fill ~6 ~53 ~64 ~101 ~55 ~64 minecraft:stone ["stone_type"="stone"]
fill ~6 ~54 ~72 ~7 ~76 ~73 minecraft:stone ["stone_type"="stone"]
fill ~6 ~61 ~34 ~97 ~63 ~34 minecraft:stone ["stone_type"="stone"]
fill ~6 ~63 ~33 ~97 ~63 ~34 minecraft:stone ["stone_type"="stone"]
fill ~6 ~64 ~33 ~81 ~74 ~37 minecraft:stone ["stone_type"="stone"]
fill ~6 ~75 ~33 ~7 ~76 ~33 minecraft:stone ["stone_type"="stone"]
fill ~6 ~75 ~34 ~7 ~75 ~35 minecraft:stone ["stone_type"="stone"]
fill ~6 ~75 ~47 ~102 ~75 ~60 minecraft:stone ["stone_type"="stone"]
fill ~6 ~76 ~34 ~6 ~76 ~35 minecraft:stone ["stone_type"="stone"]
fill ~6 ~76 ~36 ~10 ~76 ~37 minecraft:water ["liquid_depth"=0]
fill ~6 ~76 ~41 ~8 ~76 ~43 minecraft:stone ["stone_type"="stone"]
fill ~6 ~76 ~50 ~102 ~76 ~50 minecraft:stone ["stone_type"="stone"]
fill ~6 ~76 ~51 ~6 ~76 ~54 minecraft:flowing_water ["liquid_depth"=8]
fill ~6 ~77 ~40 ~7 ~77 ~40 minecraft:red_mushroom
fill ~6 ~77 ~41 ~6 ~77 ~42 minecraft:gold_block
fill ~6 ~77 ~56 ~7 ~77 ~71 minecraft:stone ["stone_type"="stone"]
fill ~6 ~77 ~72 ~6 ~79 ~72 minecraft:magma
fill ~6 ~77 ~73 ~98 ~77 ~73 minecraft:stone ["stone_type"="stone"]
fill ~6 ~78 ~69 ~99 ~78 ~71 minecraft:stone ["stone_type"="stone"]
fill ~6 ~78 ~73 ~6 ~79 ~73 minecraft:magma
fill ~6 ~79 ~63 ~6 ~84 ~63 minecraft:nether_brick
fill ~6 ~79 ~64 ~11 ~79 ~64 minecraft:lava ["liquid_depth"=0]
fill ~6 ~79 ~65 ~7 ~79 ~71 minecraft:lava ["liquid_depth"=0]
fill ~6 ~84 ~68 ~7 ~84 ~68 minecraft:stone ["stone_type"="stone"]
fill ~6 ~85 ~69 ~6 ~114 ~69 minecraft:stone ["stone_type"="stone"]
fill ~6 ~86 ~33 ~98 ~92 ~35 minecraft:stone ["stone_type"="stone"]
fill ~6 ~86 ~36 ~7 ~86 ~38 minecraft:stone ["stone_type"="andesite"]
fill ~6 ~86 ~40 ~100 ~87 ~41 minecraft:stone ["stone_type"="stone"]
fill ~6 ~86 ~67 ~6 ~114 ~69 minecraft:stone ["stone_type"="stone"]
fill ~6 ~87 ~36 ~99 ~88 ~36 minecraft:stone ["stone_type"="stone"]
fill ~6 ~87 ~37 ~99 ~87 ~55 minecraft:stone ["stone_type"="stone"]
fill ~6 ~87 ~70 ~6 ~114 ~70 minecraft:stone ["stone_type"="stone"]
fill ~6 ~88 ~37 ~98 ~91 ~53 minecraft:stone ["stone_type"="stone"]
fill ~6 ~89 ~36 ~98 ~92 ~36 minecraft:stone ["stone_type"="stone"]
fill ~6 ~89 ~66 ~99 ~89 ~68 minecraft:stone ["stone_type"="stone"]
fill ~6 ~89 ~72 ~97 ~89 ~73 minecraft:stone ["stone_type"="stone"]
fill ~6 ~90 ~66 ~88 ~114 ~71 minecraft:stone ["stone_type"="stone"]
fill ~6 ~90 ~72 ~88 ~113 ~72 minecraft:stone ["stone_type"="stone"]
fill ~6 ~90 ~73 ~88 ~112 ~73 minecraft:stone ["stone_type"="stone"]
fill ~6 ~92 ~37 ~94 ~92 ~37 minecraft:stone ["stone_type"="stone"]
fill ~6 ~93 ~33 ~97 ~93 ~35 minecraft:stone ["stone_type"="stone"]
fill ~6 ~93 ~36 ~94 ~93 ~36 minecraft:stone ["stone_type"="stone"]
fill ~6 ~93 ~37 ~92 ~93 ~61 minecraft:stone ["stone_type"="stone"]
fill ~6 ~94 ~33 ~82 ~108 ~36 minecraft:stone ["stone_type"="stone"]
fill ~6 ~94 ~37 ~89 ~105 ~37 minecraft:stone ["stone_type"="stone"]
fill ~6 ~106 ~37 ~12 ~107 ~37 minecraft:stone ["stone_type"="stone"]
fill ~6 ~109 ~33 ~6 ~109 ~34 minecraft:dirt ["dirt_type"="normal"]
fill ~6 ~109 ~35 ~99 ~109 ~36 minecraft:stone ["stone_type"="stone"]
fill ~6 ~109 ~37 ~12 ~109 ~37 minecraft:stone ["stone_type"="stone"]
fill ~6 ~110 ~31 ~6 ~115 ~31 minecraft:ladder ["facing_direction"=4]
fill ~6 ~110 ~33 ~13 ~110 ~33 minecraft:grass
fill ~6 ~110 ~34 ~8 ~110 ~35 minecraft:grass
fill ~6 ~110 ~40 ~6 ~110 ~42 minecraft:gravel
fill ~6 ~110 ~43 ~9 ~110 ~43 minecraft:grass
fill ~6 ~110 ~44 ~6 ~110 ~45 minecraft:gravel
fill ~6 ~110 ~46 ~8 ~110 ~47 minecraft:grass
fill ~6 ~110 ~48 ~6 ~110 ~49 minecraft:stone ["stone_type"="stone"]
fill ~6 ~111 ~48 ~6 ~113 ~49 minecraft:stained_hardened_clay ["color"="red"]
fill ~6 ~111 ~53 ~6 ~113 ~53 minecraft:stained_hardened_clay ["color"="red"]
fill ~6 ~113 ~30 ~8 ~117 ~30 minecraft:leaves ["persistent_bit"=true,"update_bit"=false,"old_leaf_type"="oak"]
fill ~6 ~113 ~73 ~6 ~115 ~73 minecraft:sand ["sand_type"="red"]
fill ~6 ~114 ~28 ~8 ~115 ~30 minecraft:leaves ["persistent_bit"=true,"update_bit"=false,"old_leaf_type"="oak"]
fill ~6 ~114 ~32 ~8 ~114 ~32 minecraft:leaves ["persistent_bit"=true,"update_bit"=false,"old_leaf_type"="oak"]
fill ~6 ~114 ~72 ~6 ~115 ~73 minecraft:sand ["sand_type"="red"]
fill ~6 ~115 ~59 ~7 ~115 ~59 minecraft:dirt ["dirt_type"="normal"]
fill ~6 ~115 ~61 ~7 ~115 ~61 minecraft:grass
fill ~6 ~115 ~62 ~7 ~115 ~62 minecraft:dirt ["dirt_type"="normal"]
fill ~6 ~115 ~63 ~10 ~115 ~63 minecraft:grass
fill ~6 ~115 ~64 ~8 ~115 ~64 minecraft:grass
fill ~6 ~115 ~65 ~10 ~115 ~65 minecraft:sand ["sand_type"="normal"]
fill ~6 ~115 ~66 ~7 ~115 ~69 minecraft:dirt ["dirt_type"="normal"]
fill ~6 ~115 ~70 ~9 ~115 ~70 minecraft:sand ["sand_type"="normal"]
fill ~6 ~116 ~29 ~11 ~116 ~30 minecraft:leaves ["persistent_bit"=true,"update_bit"=false,"old_leaf_type"="oak"]
fill ~6 ~116 ~55 ~6 ~116 ~56 minecraft:tallgrass ["tall_grass_type"="tall"]
fill ~6 ~116 ~59 ~7 ~116 ~59 minecraft:grass
fill ~6 ~116 ~61 ~7 ~116 ~61 minecraft:water ["liquid_depth"=0]
fill ~6 ~116 ~62 ~7 ~116 ~62 minecraft:grass
fill ~6 ~116 ~66 ~7 ~116 ~66 minecraft:sandstone ["sand_stone_type"="default"]
fill ~6 ~116 ~67 ~7 ~116 ~68 minecraft:stone ["stone_type"="stone"]
fill ~6 ~116 ~69 ~7 ~116 ~69 minecraft:sandstone ["sand_stone_type"="default"]
fill ~6 ~117 ~29 ~9 ~117 ~31 minecraft:leaves ["persistent_bit"=true,"update_bit"=false,"old_leaf_type"="oak"]
fill ~6 ~117 ~59 ~7 ~117 ~59 minecraft:tallgrass ["tall_grass_type"="tall"]
fill ~6 ~117 ~66 ~7 ~117 ~69 minecraft:sand ["sand_type"="normal"]
fill ~6 ~118 ~31 ~8 ~118 ~31 minecraft:leaves ["persistent_bit"=true,"update_bit"=false,"old_leaf_type"="oak"]
fill ~6 ~120 ~33 ~98 ~132 ~34 minecraft:stone ["stone_type"="stone"]
fill ~6 ~121 ~37 ~99 ~131 ~37 minecraft:stone ["stone_type"="stone"]
fill ~6 ~123 ~50 ~102 ~129 ~50 minecraft:stone ["stone_type"="stone"]
fill ~6 ~124 ~62 ~101 ~130 ~62 minecraft:stone ["stone_type"="stone"]
fill ~6 ~125 ~68 ~100 ~129 ~68 minecraft:stone ["stone_type"="stone"]
fill ~6 ~126 ~72 ~98 ~127 ~72 minecraft:stone ["stone_type"="stone"]
fill ~6 ~126 ~73 ~98 ~126 ~73 minecraft:stone ["stone_type"="stone"]
fill ~6 ~127 ~73 ~97 ~127 ~73 minecraft:stone ["stone_type"="stone"]
fill ~6 ~128 ~72 ~90 ~148 ~72 minecraft:stone ["stone_type"="stone"]
fill ~6 ~128 ~73 ~89 ~149 ~73 minecraft:stone ["stone_type"="stone"]
fill ~6 ~133 ~33 ~97 ~134 ~40 minecraft:stone ["stone_type"="stone"]
fill ~6 ~135 ~33 ~88 ~143 ~33 minecraft:stone ["stone_type"="stone"]
fill ~6 ~135 ~34 ~89 ~142 ~73 minecraft:stone ["stone_type"="stone"]
fill ~6 ~143 ~34 ~6 ~144 ~34 minecraft:log ["pillar_axis"="y","old_log_type"="spruce"]
fill ~6 ~143 ~35 ~90 ~143 ~73 minecraft:stone ["stone_type"="stone"]
fill ~6 ~144 ~33 ~6 ~144 ~34 minecraft:log ["pillar_axis"="y","old_log_type"="spruce"]
fill ~6 ~144 ~35 ~15 ~144 ~59 minecraft:stone ["stone_type"="stone"]
fill ~6 ~145 ~33 ~6 ~145 ~37 minecraft:wood ["stripped_bit"=false,"pillar_axis"="y","wood_type"="spruce"]
fill ~6 ~145 ~51 ~7 ~145 ~54 minecraft:dirt ["dirt_type"="normal"]
fill ~6 ~146 ~47 ~6 ~148 ~47 minecraft:dirt ["dirt_type"="normal"]
fill ~6 ~146 ~70 ~99 ~148 ~71 minecraft:stone ["stone_type"="stone"]
fill ~6 ~147 ~60 ~13 ~148 ~60 minecraft:stone ["stone_type"="stone"]
fill ~6 ~148 ~48 ~6 ~148 ~49 minecraft:dirt ["dirt_type"="normal"]
fill ~6 ~148 ~69 ~99 ~148 ~71 minecraft:stone ["stone_type"="stone"]
fill ~6 ~149 ~47 ~10 ~149 ~48 minecraft:grass
fill ~6 ~149 ~49 ~9 ~149 ~49 minecraft:grass
fill ~6 ~149 ~56 ~6 ~149 ~57 minecraft:gravel
fill ~6 ~149 ~58 ~9 ~149 ~62 minecraft:grass
fill ~6 ~149 ~63 ~6 ~149 ~64 minecraft:gravel
fill ~6 ~149 ~65 ~7 ~149 ~71 minecraft:grass
fill ~6 ~149 ~72 ~6 ~150 ~72 minecraft:dirt ["dirt_type"="normal"]
fill ~6 ~150 ~47 ~7 ~150 ~48 minecraft:snow_layer ["covered_bit"=false,"height"=0]
fill ~6 ~150 ~49 ~6 ~150 ~51 minecraft:snow_layer ["covered_bit"=false,"height"=0]
fill ~6 ~150 ~58 ~8 ~150 ~62 minecraft:snow_layer ["covered_bit"=false,"height"=0]
fill ~6 ~150 ~65 ~7 ~150 ~69 minecraft:snow_layer ["covered_bit"=false,"height"=0]
fill ~6 ~151 ~72 ~14 ~151 ~72 minecraft:grass
fill ~6 ~151 ~73 ~6 ~157 ~73 minecraft:log ["pillar_axis"="y","old_log_type"="spruce"]
fill ~6 ~152 ~72 ~12 ~152 ~72 minecraft:snow_layer ["covered_bit"=false,"height"=0]
fill ~6 ~154 ~74 ~8 ~154 ~74 minecraft:leaves ["persistent_bit"=true,"update_bit"=false,"old_leaf_type"="spruce"]
fill ~6 ~157 ~33 ~98 ~165 ~39 minecraft:stone ["stone_type"="stone"]
fill ~6 ~160 ~72 ~98 ~162 ~73 minecraft:stone ["stone_type"="stone"]
fill ~6 ~163 ~72 ~97 ~163 ~73 minecraft:stone ["stone_type"="stone"]
fill ~6 ~164 ~72 ~94 ~164 ~73 minecraft:stone ["stone_type"="stone"]
fill ~6 ~165 ~72 ~89 ~167 ~73 minecraft:stone ["stone_type"="stone"]
fill ~6 ~166 ~33 ~97 ~167 ~37 minecraft:stone ["stone_type"="stone"]
fill ~6 ~168 ~33 ~87 ~175 ~33 minecraft:stone ["stone_type"="stone"]
fill ~6 ~168 ~34 ~87 ~174 ~45 minecraft:stone ["stone_type"="stone"]
fill ~6 ~168 ~72 ~48 ~174 ~73 minecraft:stone ["stone_type"="stone"]
fill ~6 ~175 ~34 ~6 ~176 ~34 minecraft:dirt ["dirt_type"="normal"]
fill ~6 ~175 ~69 ~93 ~176 ~71 minecraft:stone ["stone_type"="stone"]
fill ~6 ~175 ~72 ~6 ~176 ~73 minecraft:dirt ["dirt_type"="normal"]
fill ~6 ~176 ~33 ~6 ~176 ~34 minecraft:dirt ["dirt_type"="normal"]
fill ~6 ~176 ~35 ~89 ~176 ~47 minecraft:stone ["stone_type"="stone"]
fill ~6 ~177 ~33 ~15 ~177 ~33 minecraft:grass
fill ~6 ~177 ~34 ~14 ~177 ~34 minecraft:grass
fill ~6 ~177 ~63 ~9 ~177 ~65 minecraft:grass
fill ~6 ~177 ~69 ~12 ~177 ~70 minecraft:grass
fill ~6 ~177 ~71 ~10 ~177 ~71 minecraft:grass
fill ~6 ~177 ~72 ~6 ~177 ~73 minecraft:grass
fill ~6 ~178 ~35 ~6 ~178 ~36 minecraft:leaves ["persistent_bit"=false,"update_bit"=false,"old_leaf_type"="jungle"]
fill ~6 ~178 ~38 ~8 ~178 ~38 minecraft:leaves ["persistent_bit"=false,"update_bit"=false,"old_leaf_type"="jungle"]
fill ~6 ~178 ~40 ~7 ~178 ~40 minecraft:leaves ["persistent_bit"=true,"update_bit"=false,"old_leaf_type"="jungle"]
fill ~6 ~178 ~42 ~7 ~178 ~42 minecraft:leaves ["persistent_bit"=true,"update_bit"=false,"old_leaf_type"="jungle"]
fill ~6 ~178 ~48 ~7 ~178 ~50 minecraft:leaves ["persistent_bit"=false,"update_bit"=false,"old_leaf_type"="jungle"]
fill ~6 ~178 ~59 ~6 ~178 ~60 minecraft:leaves ["persistent_bit"=false,"update_bit"=false,"old_leaf_type"="jungle"]
fill ~6 ~179 ~61 ~6 ~179 ~62 minecraft:leaves ["persistent_bit"=true,"update_bit"=false,"old_leaf_type"="jungle"]
fill ~6 ~181 ~34 ~8 ~182 ~34 minecraft:leaves ["persistent_bit"=true,"update_bit"=false,"old_leaf_type"="jungle"]
fill ~6 ~181 ~35 ~6 ~184 ~35 minecraft:leaves ["persistent_bit"=true,"update_bit"=false,"old_leaf_type"="jungle"]
fill ~6 ~181 ~36 ~8 ~182 ~36 minecraft:leaves ["persistent_bit"=true,"update_bit"=false,"old_leaf_type"="jungle"]
fill ~6 ~181 ~37 ~9 ~182 ~37 minecraft:leaves ["persistent_bit"=false,"update_bit"=false,"old_leaf_type"="jungle"]
fill ~6 ~181 ~64 ~10 ~181 ~64 minecraft:leaves ["persistent_bit"=false,"update_bit"=false,"old_leaf_type"="jungle"]
fill ~6 ~181 ~65 ~6 ~182 ~67 minecraft:leaves ["persistent_bit"=false,"update_bit"=false,"old_leaf_type"="jungle"]
fill ~6 ~182 ~33 ~9 ~182 ~33 minecraft:leaves ["persistent_bit"=false,"update_bit"=false,"old_leaf_type"="jungle"]
fill ~6 ~182 ~58 ~6 ~184 ~58 minecraft:vine ["vine_direction_bits"=4]
fill ~6 ~182 ~64 ~9 ~182 ~64 minecraft:leaves ["persistent_bit"=false,"update_bit"=false,"old_leaf_type"="jungle"]
fill ~6 ~182 ~68 ~9 ~182 ~68 minecraft:leaves ["persistent_bit"=false,"update_bit"=false,"old_leaf_type"="jungle"]
fill ~6 ~183 ~34 ~7 ~183 ~34 minecraft:leaves ["persistent_bit"=true,"update_bit"=false,"old_leaf_type"="jungle"]
fill ~6 ~183 ~55 ~6 ~187 ~55 minecraft:vine ["vine_direction_bits"=1]
fill ~6 ~185 ~59 ~7 ~185 ~62 minecraft:leaves ["persistent_bit"=false,"update_bit"=false,"old_leaf_type"="jungle"]
fill ~6 ~185 ~70 ~8 ~186 ~70 minecraft:leaves ["persistent_bit"=false,"update_bit"=false,"old_leaf_type"="jungle"]
fill ~6 ~185 ~71 ~8 ~187 ~71 minecraft:leaves ["persistent_bit"=true,"update_bit"=false,"old_leaf_type"="jungle"]
fill ~6 ~185 ~72 ~6 ~188 ~73 minecraft:leaves ["persistent_bit"=true,"update_bit"=false,"old_leaf_type"="jungle"]
fill ~6 ~185 ~75 ~8 ~185 ~78 minecraft:leaves ["persistent_bit"=false,"update_bit"=false,"old_leaf_type"="jungle"]
fill ~6 ~186 ~58 ~6 ~188 ~58 minecraft:vine ["vine_direction_bits"=4]
fill ~6 ~186 ~60 ~7 ~186 ~60 minecraft:leaves ["persistent_bit"=false,"update_bit"=false,"old_leaf_type"="jungle"]
fill ~6 ~186 ~74 ~9 ~186 ~74 minecraft:leaves ["persistent_bit"=false,"update_bit"=false,"old_leaf_type"="jungle"]
fill ~6 ~186 ~76 ~7 ~186 ~76 minecraft:leaves ["persistent_bit"=false,"update_bit"=false,"old_leaf_type"="jungle"]
fill ~6 ~188 ~74 ~12 ~188 ~74 minecraft:leaves ["persistent_bit"=false,"update_bit"=false,"old_leaf_type"="jungle"]
fill ~6 ~188 ~75 ~8 ~188 ~80 minecraft:leaves ["persistent_bit"=false,"update_bit"=false,"old_leaf_type"="jungle"]
fill ~6 ~189 ~76 ~8 ~189 ~77 minecraft:leaves ["persistent_bit"=false,"update_bit"=false,"old_leaf_type"="jungle"]
fill ~6 ~190 ~56 ~7 ~190 ~58 minecraft:leaves ["persistent_bit"=true,"update_bit"=false,"old_leaf_type"="jungle"]
fill ~7 ~0 ~31 ~78 ~9 ~75 minecraft:stone ["stone_type"="stone"]
fill ~79 ~0 ~31 ~97 ~9 ~75 minecraft:stone ["stone_type"="stone"]
fill ~7 ~10 ~31 ~7 ~10 ~32 minecraft:stone ["stone_type"="stone"]
fill ~7 ~10 ~33 ~9 ~10 ~33 minecraft:stone ["stone_type"="andesite"]
fill ~7 ~10 ~35 ~7 ~10 ~37 minecraft:lava ["liquid_depth"=0]
fill ~7 ~10 ~40 ~100 ~11 ~68 minecraft:stone ["stone_type"="stone"]
fill ~7 ~10 ~72 ~98 ~14 ~73 minecraft:stone ["stone_type"="stone"]
fill ~7 ~10 ~74 ~97 ~12 ~75 minecraft:stone ["stone_type"="stone"]
fill ~7 ~11 ~33 ~7 ~12 ~33 minecraft:stone ["stone_type"="stone"]
fill ~7 ~11 ~38 ~7 ~11 ~39 minecraft:stone ["stone_type"="andesite"]
fill ~7 ~12 ~34 ~7 ~13 ~34 minecraft:stone ["stone_type"="stone"]
fill ~7 ~12 ~43 ~14 ~12 ~43 minecraft:dirt ["dirt_type"="normal"]
fill ~7 ~12 ~44 ~9 ~12 ~44 minecraft:grass
fill ~7 ~12 ~46 ~10 ~12 ~51 minecraft:grass
fill ~7 ~12 ~53 ~8 ~12 ~53 minecraft:grass
fill ~7 ~12 ~54 ~7 ~12 ~58 minecraft:water ["liquid_depth"=0]
fill ~7 ~12 ~59 ~8 ~12 ~59 minecraft:grass
fill ~7 ~12 ~60 ~7 ~12 ~61 minecraft:grass
fill ~7 ~12 ~62 ~14 ~12 ~66 minecraft:dirt ["dirt_type"="normal"]
fill ~7 ~13 ~43 ~13 ~13 ~43 minecraft:grass
fill ~7 ~13 ~47 ~11 ~13 ~47 minecraft:tallgrass ["tall_grass_type"="tall"]
fill ~7 ~13 ~50 ~7 ~13 ~53 minecraft:tallgrass ["tall_grass_type"="tall"]
fill ~7 ~13 ~62 ~7 ~15 ~62 minecraft:stone ["stone_type"="stone"]
fill ~7 ~13 ~63 ~14 ~13 ~64 minecraft:dirt ["dirt_type"="normal"]
fill ~7 ~13 ~66 ~14 ~13 ~66 minecraft:dirt ["dirt_type"="normal"]
fill ~7 ~13 ~74 ~7 ~15 ~74 minecraft:end_stone
fill ~7 ~14 ~33 ~7 ~14 ~34 minecraft:stone_block_slab ["stone_slab_type"="cobblestone","top_slot_bit"=false]
fill ~7 ~14 ~49 ~7 ~17 ~49 minecraft:leaves ["persistent_bit"=true,"update_bit"=false,"old_leaf_type"="oak"]
fill ~7 ~14 ~63 ~101 ~15 ~63 minecraft:stone ["stone_type"="stone"]
fill ~7 ~14 ~64 ~101 ~14 ~64 minecraft:stone ["stone_type"="stone"]
fill ~7 ~14 ~66 ~100 ~14 ~68 minecraft:stone ["stone_type"="stone"]
fill ~7 ~14 ~75 ~7 ~15 ~75 minecraft:end_stone
fill ~7 ~15 ~65 ~9 ~15 ~65 minecraft:end_stone
fill ~7 ~15 ~70 ~10 ~15 ~71 minecraft:end_stone
fill ~7 ~15 ~72 ~7 ~15 ~73 minecraft:end_bricks
fill ~7 ~16 ~71 ~7 ~17 ~71 minecraft:chorus_plant
fill ~7 ~16 ~74 ~7 ~17 ~74 minecraft:chorus_plant
fill ~7 ~17 ~70 ~7 ~20 ~70 minecraft:chorus_plant
fill ~7 ~17 ~75 ~7 ~18 ~75 minecraft:chorus_plant
fill ~7 ~20 ~31 ~9 ~37 ~31 minecraft:stone ["stone_type"="stone"]
fill ~7 ~20 ~32 ~9 ~36 ~32 minecraft:stone ["stone_type"="stone"]
fill ~7 ~21 ~34 ~98 ~25 ~34 minecraft:stone ["stone_type"="stone"]
fill ~7 ~21 ~37 ~9 ~21 ~37 minecraft:stone ["stone_type"="stone"]
fill ~7 ~21 ~51 ~8 ~38 ~51 minecraft:stone ["stone_type"="stone"]
fill ~7 ~21 ~58 ~102 ~23 ~58 minecraft:stone ["stone_type"="stone"]
fill ~7 ~22 ~40 ~100 ~23 ~59 minecraft:stone ["stone_type"="stone"]
fill ~7 ~22 ~60 ~7 ~22 ~61 minecraft:stone ["stone_type"="andesite"]
fill ~7 ~22 ~62 ~101 ~22 ~62 minecraft:stone ["stone_type"="stone"]
fill ~7 ~23 ~36 ~7 ~38 ~36 minecraft:stone ["stone_type"="stone"]
fill ~7 ~23 ~60 ~102 ~23 ~60 minecraft:stone ["stone_type"="stone"]
fill ~7 ~23 ~65 ~101 ~23 ~65 minecraft:stone ["stone_type"="stone"]
fill ~7 ~25 ~74 ~89 ~25 ~74 minecraft:stone ["stone_type"="stone"]
fill ~7 ~25 ~75 ~88 ~27 ~75 minecraft:stone ["stone_type"="stone"]
fill ~7 ~26 ~34 ~97 ~26 ~37 minecraft:stone ["stone_type"="stone"]
fill ~7 ~26 ~74 ~88 ~39 ~74 minecraft:stone ["stone_type"="stone"]
fill ~7 ~27 ~34 ~89 ~30 ~72 minecraft:stone ["stone_type"="stone"]
fill ~7 ~28 ~75 ~87 ~40 ~75 minecraft:stone ["stone_type"="stone"]
fill ~7 ~31 ~34 ~88 ~38 ~75 minecraft:stone ["stone_type"="stone"]
fill ~7 ~37 ~32 ~7 ~39 ~32 minecraft:netherrack
fill ~7 ~38 ~31 ~7 ~40 ~31 minecraft:netherrack
fill ~7 ~38 ~33 ~98 ~38 ~73 minecraft:stone ["stone_type"="stone"]
fill ~7 ~39 ~33 ~16 ~39 ~35 minecraft:netherrack
fill ~7 ~39 ~39 ~9 ~39 ~39 minecraft:lava ["liquid_depth"=0]
fill ~7 ~39 ~47 ~7 ~39 ~49 minecraft:magma
fill ~7 ~39 ~51 ~16 ~39 ~52 minecraft:netherrack
fill ~7 ~39 ~72 ~98 ~41 ~73 minecraft:stone ["stone_type"="stone"]
fill ~7 ~40 ~74 ~7 ~41 ~74 minecraft:dirt ["dirt_type"="normal"]
fill ~7 ~42 ~57 ~102 ~42 ~60 minecraft:stone ["stone_type"="stone"]
fill ~7 ~42 ~70 ~8 ~42 ~70 minecraft:dirt ["dirt_type"="normal"]
fill ~7 ~42 ~74 ~9 ~42 ~74 minecraft:grass
fill ~7 ~42 ~75 ~8 ~42 ~75 minecraft:grass
fill ~7 ~43 ~57 ~7 ~43 ~58 minecraft:grass
fill ~7 ~43 ~59 ~9 ~43 ~59 minecraft:stone ["stone_type"="stone"]
fill ~7 ~43 ~61 ~9 ~43 ~61 minecraft:stone ["stone_type"="stone"]
fill ~7 ~43 ~67 ~8 ~43 ~67 minecraft:tallgrass ["tall_grass_type"="tall"]
fill ~7 ~43 ~70 ~8 ~45 ~70 minecraft:planks ["wood_type"="oak"]
fill ~7 ~44 ~59 ~8 ~44 ~59 minecraft:stone ["stone_type"="stone"]
fill ~7 ~45 ~59 ~7 ~45 ~61 minecraft:grass
fill ~7 ~45 ~69 ~8 ~45 ~70 minecraft:planks ["wood_type"="oak"]
fill ~7 ~48 ~68 ~8 ~48 ~70 minecraft:planks ["wood_type"="oak"]
fill ~7 ~50 ~31 ~97 ~62 ~31 minecraft:stone ["stone_type"="stone"]
fill ~7 ~50 ~32 ~97 ~61 ~37 minecraft:stone ["stone_type"="stone"]
fill ~7 ~50 ~43 ~101 ~59 ~46 minecraft:stone ["stone_type"="stone"]
fill ~7 ~50 ~47 ~102 ~57 ~47 minecraft:stone ["stone_type"="stone"]
fill ~7 ~51 ~53 ~102 ~56 ~53 minecraft:stone ["stone_type"="stone"]
fill ~7 ~52 ~60 ~102 ~57 ~60 minecraft:stone ["stone_type"="stone"]
fill ~7 ~55 ~74 ~10 ~77 ~74 minecraft:stone ["stone_type"="stone"]
fill ~7 ~56 ~75 ~74 ~69 ~75 minecraft:stone ["stone_type"="stone"]
fill ~7 ~62 ~32 ~96 ~63 ~35 minecraft:stone ["stone_type"="stone"]
fill ~7 ~63 ~31 ~96 ~63 ~35 minecraft:stone ["stone_type"="stone"]
fill ~7 ~64 ~31 ~81 ~75 ~31 minecraft:stone ["stone_type"="stone"]
fill ~7 ~64 ~32 ~81 ~74 ~37 minecraft:stone ["stone_type"="stone"]
fill ~7 ~70 ~75 ~29 ~77 ~75 minecraft:stone ["stone_type"="stone"]
fill ~7 ~75 ~32 ~8 ~75 ~32 minecraft:stone ["stone_type"="stone"]
fill ~7 ~75 ~36 ~9 ~75 ~37 minecraft:flowing_water ["liquid_depth"=8]
fill ~7 ~75 ~44 ~101 ~76 ~44 minecraft:stone ["stone_type"="stone"]
fill ~7 ~75 ~45 ~101 ~75 ~65 minecraft:stone ["stone_type"="stone"]
fill ~7 ~76 ~31 ~8 ~76 ~31 minecraft:stone ["stone_type"="stone"]
fill ~7 ~76 ~32 ~7 ~76 ~33 minecraft:stone ["stone_type"="stone"]
fill ~7 ~76 ~34 ~11 ~76 ~35 minecraft:water ["liquid_depth"=0]
fill ~7 ~76 ~38 ~12 ~76 ~39 minecraft:water ["liquid_depth"=0]
fill ~7 ~76 ~40 ~7 ~76 ~44 minecraft:stone ["stone_type"="stone"]
fill ~7 ~76 ~51 ~102 ~76 ~54 minecraft:stone ["stone_type"="stone"]
fill ~7 ~77 ~49 ~102 ~77 ~49 minecraft:stone ["stone_type"="stone"]
fill ~7 ~77 ~50 ~7 ~77 ~54 minecraft:water ["liquid_depth"=0]
fill ~7 ~77 ~55 ~7 ~77 ~75 minecraft:stone ["stone_type"="stone"]
fill ~7 ~78 ~72 ~98 ~78 ~73 minecraft:stone ["stone_type"="stone"]
fill ~7 ~78 ~74 ~7 ~79 ~75 minecraft:magma
fill ~7 ~79 ~63 ~10 ~79 ~64 minecraft:lava ["liquid_depth"=0]
fill ~7 ~79 ~72 ~13 ~79 ~73 minecraft:lava ["liquid_depth"=0]
fill ~7 ~85 ~34 ~9 ~109 ~34 minecraft:stone ["stone_type"="stone"]
fill ~7 ~85 ~35 ~9 ~85 ~35 minecraft:stone ["stone_type"="andesite"]
fill ~7 ~86 ~31 ~97 ~91 ~35 minecraft:stone ["stone_type"="stone"]
fill ~7 ~86 ~39 ~100 ~87 ~45 minecraft:stone ["stone_type"="stone"]
fill ~7 ~86 ~52 ~102 ~86 ~53 minecraft:stone ["stone_type"="stone"]
fill ~7 ~87 ~56 ~102 ~88 ~57 minecraft:stone ["stone_type"="stone"]
fill ~7 ~88 ~60 ~102 ~88 ~60 minecraft:stone ["stone_type"="stone"]
fill ~7 ~88 ~69 ~7 ~114 ~69 minecraft:stone ["stone_type"="stone"]
fill ~7 ~88 ~71 ~7 ~114 ~71 minecraft:stone ["stone_type"="stone"]
